(0.001) QUERY = u'SELECT "gps_gpsnode"."id", "gps_gpsnode"."ident", "gps_gpsnode"."user_id", "gps_gpsnode"."last_active" FROM "gps_gpsnode" WHERE "gps_gpsnode"."id" = %s ' - PARAMS = (1,); args=(1,)
(0.000) QUERY = u'SELECT "gps_gpsnodemetrics"."id", "gps_gpsnodemetrics"."node_id", "gps_gpsnodemetrics"."latitude", "gps_gpsnodemetrics"."longitude", "gps_gpsnodemetrics"."accuracy", "gps_gpsnodemetrics"."speed", "gps_gpsnodemetrics"."altitude", "gps_gpsnodemetrics"."nsecTimestamp", "gps_gpsnodemetrics"."bearing", "gps_gpsnodemetrics"."vin", "gps_gpsnodemetrics"."vinLastCached" FROM "gps_gpsnodemetrics" WHERE "gps_gpsnodemetrics"."node_id" = %s ' - PARAMS = (1,); args=(1,)
(0.001) QUERY = u'SELECT "gps_gpsnode"."id", "gps_gpsnode"."ident", "gps_gpsnode"."user_id", "gps_gpsnode"."last_active" FROM "gps_gpsnode" WHERE "gps_gpsnode"."id" = %s ' - PARAMS = (1,); args=(1,)
(0.000) QUERY = u'SELECT "gps_gpsnodemetrics"."id", "gps_gpsnodemetrics"."node_id", "gps_gpsnodemetrics"."latitude", "gps_gpsnodemetrics"."longitude", "gps_gpsnodemetrics"."accuracy", "gps_gpsnodemetrics"."speed", "gps_gpsnodemetrics"."altitude", "gps_gpsnodemetrics"."nsecTimestamp", "gps_gpsnodemetrics"."bearing", "gps_gpsnodemetrics"."vin", "gps_gpsnodemetrics"."vinLastCached" FROM "gps_gpsnodemetrics" WHERE "gps_gpsnodemetrics"."node_id" = %s ' - PARAMS = (1,); args=(1,)
(0.001) QUERY = u'SELECT "gps_gpsnode"."id", "gps_gpsnode"."ident", "gps_gpsnode"."user_id", "gps_gpsnode"."last_active" FROM "gps_gpsnode" WHERE "gps_gpsnode"."id" = %s ' - PARAMS = (1,); args=(1,)
(0.000) QUERY = u'SELECT "gps_gpsnodemetrics"."id", "gps_gpsnodemetrics"."node_id", "gps_gpsnodemetrics"."latitude", "gps_gpsnodemetrics"."longitude", "gps_gpsnodemetrics"."accuracy", "gps_gpsnodemetrics"."speed", "gps_gpsnodemetrics"."altitude", "gps_gpsnodemetrics"."nsecTimestamp", "gps_gpsnodemetrics"."bearing", "gps_gpsnodemetrics"."vin", "gps_gpsnodemetrics"."vinLastCached" FROM "gps_gpsnodemetrics" WHERE "gps_gpsnodemetrics"."node_id" = %s ' - PARAMS = (1,); args=(1,)
(0.001) QUERY = u'SELECT "gps_gpsnode"."id", "gps_gpsnode"."ident", "gps_gpsnode"."user_id", "gps_gpsnode"."last_active" FROM "gps_gpsnode" WHERE "gps_gpsnode"."id" = %s ' - PARAMS = (1,); args=(1,)
(0.000) QUERY = u'SELECT "gps_gpsnodemetrics"."id", "gps_gpsnodemetrics"."node_id", "gps_gpsnodemetrics"."latitude", "gps_gpsnodemetrics"."longitude", "gps_gpsnodemetrics"."accuracy", "gps_gpsnodemetrics"."speed", "gps_gpsnodemetrics"."altitude", "gps_gpsnodemetrics"."nsecTimestamp", "gps_gpsnodemetrics"."bearing", "gps_gpsnodemetrics"."vin", "gps_gpsnodemetrics"."vinLastCached" FROM "gps_gpsnodemetrics" WHERE "gps_gpsnodemetrics"."node_id" = %s ' - PARAMS = (1,); args=(1,)
(0.001) QUERY = u'SELECT "gps_gpsnode"."id", "gps_gpsnode"."ident", "gps_gpsnode"."user_id", "gps_gpsnode"."last_active" FROM "gps_gpsnode" WHERE "gps_gpsnode"."id" = %s ' - PARAMS = (1,); args=(1,)
(0.000) QUERY = u'SELECT "gps_gpsnodemetrics"."id", "gps_gpsnodemetrics"."node_id", "gps_gpsnodemetrics"."latitude", "gps_gpsnodemetrics"."longitude", "gps_gpsnodemetrics"."accuracy", "gps_gpsnodemetrics"."speed", "gps_gpsnodemetrics"."altitude", "gps_gpsnodemetrics"."nsecTimestamp", "gps_gpsnodemetrics"."bearing", "gps_gpsnodemetrics"."vin", "gps_gpsnodemetrics"."vinLastCached" FROM "gps_gpsnodemetrics" WHERE "gps_gpsnodemetrics"."node_id" = %s ' - PARAMS = (1,); args=(1,)
(0.001) QUERY = u'SELECT "gps_gpsnode"."id", "gps_gpsnode"."ident", "gps_gpsnode"."user_id", "gps_gpsnode"."last_active" FROM "gps_gpsnode" WHERE "gps_gpsnode"."id" = %s ' - PARAMS = (1,); args=(1,)
(0.000) QUERY = u'SELECT "gps_gpsnodemetrics"."id", "gps_gpsnodemetrics"."node_id", "gps_gpsnodemetrics"."latitude", "gps_gpsnodemetrics"."longitude", "gps_gpsnodemetrics"."accuracy", "gps_gpsnodemetrics"."speed", "gps_gpsnodemetrics"."altitude", "gps_gpsnodemetrics"."nsecTimestamp", "gps_gpsnodemetrics"."bearing", "gps_gpsnodemetrics"."vin", "gps_gpsnodemetrics"."vinLastCached" FROM "gps_gpsnodemetrics" WHERE "gps_gpsnodemetrics"."node_id" = %s ' - PARAMS = (1,); args=(1,)
(0.001) QUERY = u'SELECT "gps_gpsnode"."id", "gps_gpsnode"."ident", "gps_gpsnode"."user_id", "gps_gpsnode"."last_active" FROM "gps_gpsnode" WHERE "gps_gpsnode"."id" = %s ' - PARAMS = (1,); args=(1,)
(0.000) QUERY = u'SELECT "gps_gpsnodemetrics"."id", "gps_gpsnodemetrics"."node_id", "gps_gpsnodemetrics"."latitude", "gps_gpsnodemetrics"."longitude", "gps_gpsnodemetrics"."accuracy", "gps_gpsnodemetrics"."speed", "gps_gpsnodemetrics"."altitude", "gps_gpsnodemetrics"."nsecTimestamp", "gps_gpsnodemetrics"."bearing", "gps_gpsnodemetrics"."vin", "gps_gpsnodemetrics"."vinLastCached" FROM "gps_gpsnodemetrics" WHERE "gps_gpsnodemetrics"."node_id" = %s ' - PARAMS = (1,); args=(1,)
(0.001) QUERY = u'SELECT "gps_gpsnode"."id", "gps_gpsnode"."ident", "gps_gpsnode"."user_id", "gps_gpsnode"."last_active" FROM "gps_gpsnode" WHERE "gps_gpsnode"."id" = %s ' - PARAMS = (1,); args=(1,)
(0.000) QUERY = u'SELECT "gps_gpsnodemetrics"."id", "gps_gpsnodemetrics"."node_id", "gps_gpsnodemetrics"."latitude", "gps_gpsnodemetrics"."longitude", "gps_gpsnodemetrics"."accuracy", "gps_gpsnodemetrics"."speed", "gps_gpsnodemetrics"."altitude", "gps_gpsnodemetrics"."nsecTimestamp", "gps_gpsnodemetrics"."bearing", "gps_gpsnodemetrics"."vin", "gps_gpsnodemetrics"."vinLastCached" FROM "gps_gpsnodemetrics" WHERE "gps_gpsnodemetrics"."node_id" = %s ' - PARAMS = (1,); args=(1,)
(0.001) QUERY = u'SELECT "gps_gpsnode"."id", "gps_gpsnode"."ident", "gps_gpsnode"."user_id", "gps_gpsnode"."last_active" FROM "gps_gpsnode" WHERE "gps_gpsnode"."id" = %s ' - PARAMS = (1,); args=(1,)
(0.000) QUERY = u'SELECT "gps_gpsnodemetrics"."id", "gps_gpsnodemetrics"."node_id", "gps_gpsnodemetrics"."latitude", "gps_gpsnodemetrics"."longitude", "gps_gpsnodemetrics"."accuracy", "gps_gpsnodemetrics"."speed", "gps_gpsnodemetrics"."altitude", "gps_gpsnodemetrics"."nsecTimestamp", "gps_gpsnodemetrics"."bearing", "gps_gpsnodemetrics"."vin", "gps_gpsnodemetrics"."vinLastCached" FROM "gps_gpsnodemetrics" WHERE "gps_gpsnodemetrics"."node_id" = %s ' - PARAMS = (1,); args=(1,)
(0.001) QUERY = u'SELECT "gps_gpsnode"."id", "gps_gpsnode"."ident", "gps_gpsnode"."user_id", "gps_gpsnode"."last_active" FROM "gps_gpsnode" WHERE "gps_gpsnode"."id" = %s ' - PARAMS = (1,); args=(1,)
(0.000) QUERY = u'SELECT "gps_gpsnodemetrics"."id", "gps_gpsnodemetrics"."node_id", "gps_gpsnodemetrics"."latitude", "gps_gpsnodemetrics"."longitude", "gps_gpsnodemetrics"."accuracy", "gps_gpsnodemetrics"."speed", "gps_gpsnodemetrics"."altitude", "gps_gpsnodemetrics"."nsecTimestamp", "gps_gpsnodemetrics"."bearing", "gps_gpsnodemetrics"."vin", "gps_gpsnodemetrics"."vinLastCached" FROM "gps_gpsnodemetrics" WHERE "gps_gpsnodemetrics"."node_id" = %s ' - PARAMS = (1,); args=(1,)
(0.001) QUERY = u'SELECT "gps_gpsnode"."id", "gps_gpsnode"."ident", "gps_gpsnode"."user_id", "gps_gpsnode"."last_active" FROM "gps_gpsnode" WHERE "gps_gpsnode"."id" = %s ' - PARAMS = (1,); args=(1,)
(0.000) QUERY = u'SELECT "gps_gpsnodemetrics"."id", "gps_gpsnodemetrics"."node_id", "gps_gpsnodemetrics"."latitude", "gps_gpsnodemetrics"."longitude", "gps_gpsnodemetrics"."accuracy", "gps_gpsnodemetrics"."speed", "gps_gpsnodemetrics"."altitude", "gps_gpsnodemetrics"."nsecTimestamp", "gps_gpsnodemetrics"."bearing", "gps_gpsnodemetrics"."vin", "gps_gpsnodemetrics"."vinLastCached" FROM "gps_gpsnodemetrics" WHERE "gps_gpsnodemetrics"."node_id" = %s ' - PARAMS = (1,); args=(1,)
(0.001) QUERY = u'SELECT "gps_gpsnode"."id", "gps_gpsnode"."ident", "gps_gpsnode"."user_id", "gps_gpsnode"."last_active" FROM "gps_gpsnode" WHERE "gps_gpsnode"."id" = %s ' - PARAMS = (1,); args=(1,)
(0.000) QUERY = u'SELECT "gps_gpsnodemetrics"."id", "gps_gpsnodemetrics"."node_id", "gps_gpsnodemetrics"."latitude", "gps_gpsnodemetrics"."longitude", "gps_gpsnodemetrics"."accuracy", "gps_gpsnodemetrics"."speed", "gps_gpsnodemetrics"."altitude", "gps_gpsnodemetrics"."nsecTimestamp", "gps_gpsnodemetrics"."bearing", "gps_gpsnodemetrics"."vin", "gps_gpsnodemetrics"."vinLastCached" FROM "gps_gpsnodemetrics" WHERE "gps_gpsnodemetrics"."node_id" = %s ' - PARAMS = (1,); args=(1,)
(0.001) QUERY = u'SELECT "gps_gpsnode"."id", "gps_gpsnode"."ident", "gps_gpsnode"."user_id", "gps_gpsnode"."last_active" FROM "gps_gpsnode" ORDER BY "gps_gpsnode"."last_active" DESC' - PARAMS = (); args=()
(0.001) QUERY = u'SELECT "gps_gpsnode"."id", "gps_gpsnode"."ident", "gps_gpsnode"."user_id", "gps_gpsnode"."last_active" FROM "gps_gpsnode" WHERE "gps_gpsnode"."id" = %s ' - PARAMS = (1,); args=(1,)
(0.000) QUERY = u'SELECT "gps_gpsnodemetrics"."id", "gps_gpsnodemetrics"."node_id", "gps_gpsnodemetrics"."latitude", "gps_gpsnodemetrics"."longitude", "gps_gpsnodemetrics"."accuracy", "gps_gpsnodemetrics"."speed", "gps_gpsnodemetrics"."altitude", "gps_gpsnodemetrics"."nsecTimestamp", "gps_gpsnodemetrics"."bearing", "gps_gpsnodemetrics"."vin", "gps_gpsnodemetrics"."vinLastCached" FROM "gps_gpsnodemetrics" WHERE "gps_gpsnodemetrics"."node_id" = %s ' - PARAMS = (1,); args=(1,)
(0.001) QUERY = u'SELECT "gps_gpsnode"."id", "gps_gpsnode"."ident", "gps_gpsnode"."user_id", "gps_gpsnode"."last_active" FROM "gps_gpsnode" WHERE "gps_gpsnode"."id" = %s ' - PARAMS = (1,); args=(1,)
(0.000) QUERY = u'SELECT "gps_gpsnodemetrics"."id", "gps_gpsnodemetrics"."node_id", "gps_gpsnodemetrics"."latitude", "gps_gpsnodemetrics"."longitude", "gps_gpsnodemetrics"."accuracy", "gps_gpsnodemetrics"."speed", "gps_gpsnodemetrics"."altitude", "gps_gpsnodemetrics"."nsecTimestamp", "gps_gpsnodemetrics"."bearing", "gps_gpsnodemetrics"."vin", "gps_gpsnodemetrics"."vinLastCached" FROM "gps_gpsnodemetrics" WHERE "gps_gpsnodemetrics"."node_id" = %s ' - PARAMS = (1,); args=(1,)
(0.001) QUERY = u'SELECT "gps_gpsnode"."id", "gps_gpsnode"."ident", "gps_gpsnode"."user_id", "gps_gpsnode"."last_active" FROM "gps_gpsnode" WHERE "gps_gpsnode"."id" = %s ' - PARAMS = (1,); args=(1,)
(0.000) QUERY = u'SELECT "gps_gpsnodemetrics"."id", "gps_gpsnodemetrics"."node_id", "gps_gpsnodemetrics"."latitude", "gps_gpsnodemetrics"."longitude", "gps_gpsnodemetrics"."accuracy", "gps_gpsnodemetrics"."speed", "gps_gpsnodemetrics"."altitude", "gps_gpsnodemetrics"."nsecTimestamp", "gps_gpsnodemetrics"."bearing", "gps_gpsnodemetrics"."vin", "gps_gpsnodemetrics"."vinLastCached" FROM "gps_gpsnodemetrics" WHERE "gps_gpsnodemetrics"."node_id" = %s ' - PARAMS = (1,); args=(1,)
Internal Server Error: /gps/1/update
Traceback (most recent call last):
  File "/usr/lib/python2.6/site-packages/django/core/handlers/base.py", line 112, in get_response
    response = wrapped_callback(request, *callback_args, **callback_kwargs)
TypeError: updateForm() got an unexpected keyword argument 'id'
(0.001) QUERY = u'SELECT "gps_gpsnode"."id", "gps_gpsnode"."ident", "gps_gpsnode"."user_id", "gps_gpsnode"."last_active" FROM "gps_gpsnode" WHERE "gps_gpsnode"."id" = %s ' - PARAMS = (1,); args=(1,)
(0.000) QUERY = u'SELECT "gps_gpsnodemetrics"."id", "gps_gpsnodemetrics"."node_id", "gps_gpsnodemetrics"."latitude", "gps_gpsnodemetrics"."longitude", "gps_gpsnodemetrics"."accuracy", "gps_gpsnodemetrics"."speed", "gps_gpsnodemetrics"."altitude", "gps_gpsnodemetrics"."nsecTimestamp", "gps_gpsnodemetrics"."bearing", "gps_gpsnodemetrics"."vin", "gps_gpsnodemetrics"."vinLastCached" FROM "gps_gpsnodemetrics" WHERE "gps_gpsnodemetrics"."node_id" = %s ' - PARAMS = (1,); args=(1,)
Internal Server Error: /gps/1/update
Traceback (most recent call last):
  File "/usr/lib/python2.6/site-packages/django/core/handlers/base.py", line 112, in get_response
    response = wrapped_callback(request, *callback_args, **callback_kwargs)
  File "/home/sulakshm/work/django/rest/automon/gps/views.py", line 43, in updateForm
    log.info("view.updateForm(request = %r, node = %r)", request, node)
NameError: global name 'node' is not defined
Internal Server Error: /gps/1/update
Traceback (most recent call last):
  File "/usr/lib/python2.6/site-packages/django/core/handlers/base.py", line 130, in get_response
    raise ValueError("The view %s.%s didn't return an HttpResponse object." % (callback.__module__, view_name))
ValueError: The view gps.views.updateForm didn't return an HttpResponse object.
(0.001) QUERY = u'SELECT "gps_gpsnode"."id", "gps_gpsnode"."ident", "gps_gpsnode"."user_id", "gps_gpsnode"."last_active" FROM "gps_gpsnode" WHERE "gps_gpsnode"."id" = %s ' - PARAMS = (1,); args=(1,)
(0.000) QUERY = u'SELECT "gps_gpsnodemetrics"."id", "gps_gpsnodemetrics"."node_id", "gps_gpsnodemetrics"."latitude", "gps_gpsnodemetrics"."longitude", "gps_gpsnodemetrics"."accuracy", "gps_gpsnodemetrics"."speed", "gps_gpsnodemetrics"."altitude", "gps_gpsnodemetrics"."nsecTimestamp", "gps_gpsnodemetrics"."bearing", "gps_gpsnodemetrics"."vin", "gps_gpsnodemetrics"."vinLastCached" FROM "gps_gpsnodemetrics" WHERE "gps_gpsnodemetrics"."node_id" = %s ' - PARAMS = (1,); args=(1,)
(0.001) QUERY = u'SELECT "gps_gpsnode"."id", "gps_gpsnode"."ident", "gps_gpsnode"."user_id", "gps_gpsnode"."last_active" FROM "gps_gpsnode" WHERE "gps_gpsnode"."id" = %s ' - PARAMS = (1,); args=(1,)
(0.000) QUERY = u'SELECT "gps_gpsnodemetrics"."id", "gps_gpsnodemetrics"."node_id", "gps_gpsnodemetrics"."latitude", "gps_gpsnodemetrics"."longitude", "gps_gpsnodemetrics"."accuracy", "gps_gpsnodemetrics"."speed", "gps_gpsnodemetrics"."altitude", "gps_gpsnodemetrics"."nsecTimestamp", "gps_gpsnodemetrics"."bearing", "gps_gpsnodemetrics"."vin", "gps_gpsnodemetrics"."vinLastCached" FROM "gps_gpsnodemetrics" WHERE "gps_gpsnodemetrics"."node_id" = %s ' - PARAMS = (1,); args=(1,)
Internal Server Error: /gps/1/
Traceback (most recent call last):
  File "/usr/lib/python2.6/site-packages/django/core/handlers/base.py", line 99, in get_response
    resolver_match = resolver.resolve(request.path_info)
  File "/usr/lib/python2.6/site-packages/django/core/urlresolvers.py", line 337, in resolve
    for pattern in self.url_patterns:
  File "/usr/lib/python2.6/site-packages/django/core/urlresolvers.py", line 365, in url_patterns
    patterns = getattr(self.urlconf_module, "urlpatterns", self.urlconf_module)
  File "/usr/lib/python2.6/site-packages/django/core/urlresolvers.py", line 360, in urlconf_module
    self._urlconf_module = import_module(self.urlconf_name)
  File "/usr/lib/python2.6/site-packages/django/utils/importlib.py", line 40, in import_module
    __import__(name)
  File "/home/sulakshm/work/django/rest/automon/automon/urls.py", line 11, in <module>
    url(r'^gps/', include('gps.urls', namespace='gps')),
  File "/usr/lib/python2.6/site-packages/django/conf/urls/__init__.py", line 26, in include
    urlconf_module = import_module(urlconf_module)
  File "/usr/lib/python2.6/site-packages/django/utils/importlib.py", line 40, in import_module
    __import__(name)
  File "/home/sulakshm/work/django/rest/automon/gps/urls.py", line 3, in <module>
    from gps import views
  File "/home/sulakshm/work/django/rest/automon/gps/views.py", line 3, in <module>
    from django import ModelForm
ImportError: cannot import name ModelForm
Internal Server Error: /gps/
Traceback (most recent call last):
  File "/usr/lib/python2.6/site-packages/django/core/handlers/base.py", line 99, in get_response
    resolver_match = resolver.resolve(request.path_info)
  File "/usr/lib/python2.6/site-packages/django/core/urlresolvers.py", line 337, in resolve
    for pattern in self.url_patterns:
  File "/usr/lib/python2.6/site-packages/django/core/urlresolvers.py", line 365, in url_patterns
    patterns = getattr(self.urlconf_module, "urlpatterns", self.urlconf_module)
  File "/usr/lib/python2.6/site-packages/django/core/urlresolvers.py", line 360, in urlconf_module
    self._urlconf_module = import_module(self.urlconf_name)
  File "/usr/lib/python2.6/site-packages/django/utils/importlib.py", line 40, in import_module
    __import__(name)
  File "/home/sulakshm/work/django/rest/automon/automon/urls.py", line 11, in <module>
    url(r'^gps/', include('gps.urls', namespace='gps')),
  File "/usr/lib/python2.6/site-packages/django/conf/urls/__init__.py", line 26, in include
    urlconf_module = import_module(urlconf_module)
  File "/usr/lib/python2.6/site-packages/django/utils/importlib.py", line 40, in import_module
    __import__(name)
  File "/home/sulakshm/work/django/rest/automon/gps/urls.py", line 3, in <module>
    from gps import views
  File "/home/sulakshm/work/django/rest/automon/gps/views.py", line 40, in <module>
    class MetricForm(ModelForm):
  File "/usr/lib/python2.6/site-packages/django/forms/models.py", line 292, in __new__
    raise FieldError(message)
FieldError: Unknown field(s) (VINCached, Bearing, Altitude, VIN, Longitude, NanosecTimestamp, Latitude, Speed, Accuracy) specified for GpsNodeMetrics
(0.001) QUERY = u'SELECT "gps_gpsnode"."id", "gps_gpsnode"."ident", "gps_gpsnode"."user_id", "gps_gpsnode"."last_active" FROM "gps_gpsnode" ORDER BY "gps_gpsnode"."last_active" DESC' - PARAMS = (); args=()
(0.001) QUERY = u'SELECT "gps_gpsnode"."id", "gps_gpsnode"."ident", "gps_gpsnode"."user_id", "gps_gpsnode"."last_active" FROM "gps_gpsnode" WHERE "gps_gpsnode"."id" = %s ' - PARAMS = (1,); args=(1,)
Internal Server Error: /gps/1/
Traceback (most recent call last):
  File "/usr/lib/python2.6/site-packages/django/core/handlers/base.py", line 112, in get_response
    response = wrapped_callback(request, *callback_args, **callback_kwargs)
  File "/home/sulakshm/work/django/rest/automon/gps/views.py", line 24, in showAll
    return render(request, 'gps/showAll.html', {'node' : node})
  File "/usr/lib/python2.6/site-packages/django/shortcuts/__init__.py", line 53, in render
    return HttpResponse(loader.render_to_string(*args, **kwargs),
  File "/usr/lib/python2.6/site-packages/django/template/loader.py", line 169, in render_to_string
    return t.render(context_instance)
  File "/usr/lib/python2.6/site-packages/django/template/base.py", line 140, in render
    return self._render(context)
  File "/usr/lib/python2.6/site-packages/django/template/base.py", line 134, in _render
    return self.nodelist.render(context)
  File "/usr/lib/python2.6/site-packages/django/template/base.py", line 840, in render
    bit = self.render_node(node, context)
  File "/usr/lib/python2.6/site-packages/django/template/debug.py", line 78, in render_node
    return node.render(context)
  File "/usr/lib/python2.6/site-packages/django/template/defaulttags.py", line 447, in render
    six.reraise(*exc_info)
  File "/usr/lib/python2.6/site-packages/django/template/defaulttags.py", line 433, in render
    url = reverse(view_name, args=args, kwargs=kwargs, current_app=context.current_app)
  File "/usr/lib/python2.6/site-packages/django/core/urlresolvers.py", line 536, in reverse
    return iri_to_uri(resolver._reverse_with_prefix(view, prefix, *args, **kwargs))
  File "/usr/lib/python2.6/site-packages/django/core/urlresolvers.py", line 456, in _reverse_with_prefix
    (lookup_view_s, args, kwargs, len(patterns), patterns))
NoReverseMatch: Reverse for 'updateForm' with arguments '(1,)' and keyword arguments '{}' not found. 0 pattern(s) tried: []
(0.001) QUERY = u'SELECT "gps_gpsnode"."id", "gps_gpsnode"."ident", "gps_gpsnode"."user_id", "gps_gpsnode"."last_active" FROM "gps_gpsnode" WHERE "gps_gpsnode"."id" = %s ' - PARAMS = (1,); args=(1,)
(0.000) QUERY = u'SELECT "gps_gpsnodemetrics"."id", "gps_gpsnodemetrics"."node_id", "gps_gpsnodemetrics"."latitude", "gps_gpsnodemetrics"."longitude", "gps_gpsnodemetrics"."accuracy", "gps_gpsnodemetrics"."speed", "gps_gpsnodemetrics"."altitude", "gps_gpsnodemetrics"."nsecTimestamp", "gps_gpsnodemetrics"."bearing", "gps_gpsnodemetrics"."vin", "gps_gpsnodemetrics"."vinLastCached" FROM "gps_gpsnodemetrics" WHERE "gps_gpsnodemetrics"."node_id" = %s ' - PARAMS = (1,); args=(1,)
Internal Server Error: /gps/1/update
Traceback (most recent call last):
  File "/usr/lib/python2.6/site-packages/django/core/handlers/base.py", line 112, in get_response
    response = wrapped_callback(request, *callback_args, **callback_kwargs)
TypeError: update() got an unexpected keyword argument 'id'
(0.001) QUERY = u'SELECT "gps_gpsnode"."id", "gps_gpsnode"."ident", "gps_gpsnode"."user_id", "gps_gpsnode"."last_active" FROM "gps_gpsnode" WHERE "gps_gpsnode"."id" = %s ' - PARAMS = (1,); args=(1,)
(0.000) QUERY = u'SELECT "gps_gpsnodemetrics"."id", "gps_gpsnodemetrics"."node_id", "gps_gpsnodemetrics"."latitude", "gps_gpsnodemetrics"."longitude", "gps_gpsnodemetrics"."accuracy", "gps_gpsnodemetrics"."speed", "gps_gpsnodemetrics"."altitude", "gps_gpsnodemetrics"."nsecTimestamp", "gps_gpsnodemetrics"."bearing", "gps_gpsnodemetrics"."vin", "gps_gpsnodemetrics"."vinLastCached" FROM "gps_gpsnodemetrics" WHERE "gps_gpsnodemetrics"."node_id" = %s ' - PARAMS = (1,); args=(1,)
Internal Server Error: /gps/1/update
Traceback (most recent call last):
  File "/usr/lib/python2.6/site-packages/django/core/handlers/base.py", line 112, in get_response
    response = wrapped_callback(request, *callback_args, **callback_kwargs)
  File "/home/sulakshm/work/django/rest/automon/gps/views.py", line 59, in update
    return render(request, 'gps/update.html', {'form' : form})
  File "/usr/lib/python2.6/site-packages/django/shortcuts/__init__.py", line 53, in render
    return HttpResponse(loader.render_to_string(*args, **kwargs),
  File "/usr/lib/python2.6/site-packages/django/template/loader.py", line 162, in render_to_string
    t = get_template(template_name)
  File "/usr/lib/python2.6/site-packages/django/template/loader.py", line 138, in get_template
    template, origin = find_template(template_name)
  File "/usr/lib/python2.6/site-packages/django/template/loader.py", line 131, in find_template
    raise TemplateDoesNotExist(name)
TemplateDoesNotExist: gps/update.html
(0.001) QUERY = u'SELECT "gps_gpsnode"."id", "gps_gpsnode"."ident", "gps_gpsnode"."user_id", "gps_gpsnode"."last_active" FROM "gps_gpsnode" WHERE "gps_gpsnode"."id" = %s ' - PARAMS = (1,); args=(1,)
(0.000) QUERY = u'SELECT "gps_gpsnodemetrics"."id", "gps_gpsnodemetrics"."node_id", "gps_gpsnodemetrics"."latitude", "gps_gpsnodemetrics"."longitude", "gps_gpsnodemetrics"."accuracy", "gps_gpsnodemetrics"."speed", "gps_gpsnodemetrics"."altitude", "gps_gpsnodemetrics"."nsecTimestamp", "gps_gpsnodemetrics"."bearing", "gps_gpsnodemetrics"."vin", "gps_gpsnodemetrics"."vinLastCached" FROM "gps_gpsnodemetrics" WHERE "gps_gpsnodemetrics"."node_id" = %s ' - PARAMS = (1,); args=(1,)
Internal Server Error: /gps/1/update
Traceback (most recent call last):
  File "/usr/lib/python2.6/site-packages/django/core/handlers/base.py", line 112, in get_response
    response = wrapped_callback(request, *callback_args, **callback_kwargs)
  File "/home/sulakshm/work/django/rest/automon/gps/views.py", line 59, in update
    return render(request, 'gps/update.html', {'form' : form})
  File "/usr/lib/python2.6/site-packages/django/shortcuts/__init__.py", line 53, in render
    return HttpResponse(loader.render_to_string(*args, **kwargs),
  File "/usr/lib/python2.6/site-packages/django/template/loader.py", line 169, in render_to_string
    return t.render(context_instance)
  File "/usr/lib/python2.6/site-packages/django/template/base.py", line 140, in render
    return self._render(context)
  File "/usr/lib/python2.6/site-packages/django/template/base.py", line 134, in _render
    return self.nodelist.render(context)
  File "/usr/lib/python2.6/site-packages/django/template/base.py", line 840, in render
    bit = self.render_node(node, context)
  File "/usr/lib/python2.6/site-packages/django/template/debug.py", line 78, in render_node
    return node.render(context)
  File "/usr/lib/python2.6/site-packages/django/template/defaulttags.py", line 447, in render
    six.reraise(*exc_info)
  File "/usr/lib/python2.6/site-packages/django/template/defaulttags.py", line 433, in render
    url = reverse(view_name, args=args, kwargs=kwargs, current_app=context.current_app)
  File "/usr/lib/python2.6/site-packages/django/core/urlresolvers.py", line 536, in reverse
    return iri_to_uri(resolver._reverse_with_prefix(view, prefix, *args, **kwargs))
  File "/usr/lib/python2.6/site-packages/django/core/urlresolvers.py", line 456, in _reverse_with_prefix
    (lookup_view_s, args, kwargs, len(patterns), patterns))
NoReverseMatch: Reverse for 'update' with arguments '('',)' and keyword arguments '{}' not found. 1 pattern(s) tried: [u'gps/(?P<id>\\d+)/update$']
(0.001) QUERY = u'SELECT "gps_gpsnode"."id", "gps_gpsnode"."ident", "gps_gpsnode"."user_id", "gps_gpsnode"."last_active" FROM "gps_gpsnode" ORDER BY "gps_gpsnode"."last_active" DESC' - PARAMS = (); args=()
(0.001) QUERY = u'SELECT "gps_gpsnode"."id", "gps_gpsnode"."ident", "gps_gpsnode"."user_id", "gps_gpsnode"."last_active" FROM "gps_gpsnode" WHERE "gps_gpsnode"."id" = %s ' - PARAMS = (1,); args=(1,)
(0.000) QUERY = u'SELECT "gps_gpsnodemetrics"."id", "gps_gpsnodemetrics"."node_id", "gps_gpsnodemetrics"."latitude", "gps_gpsnodemetrics"."longitude", "gps_gpsnodemetrics"."accuracy", "gps_gpsnodemetrics"."speed", "gps_gpsnodemetrics"."altitude", "gps_gpsnodemetrics"."nsecTimestamp", "gps_gpsnodemetrics"."bearing", "gps_gpsnodemetrics"."vin", "gps_gpsnodemetrics"."vinLastCached" FROM "gps_gpsnodemetrics" WHERE "gps_gpsnodemetrics"."node_id" = %s ' - PARAMS = (1,); args=(1,)
Internal Server Error: /gps/1/update
Traceback (most recent call last):
  File "/usr/lib/python2.6/site-packages/django/core/handlers/base.py", line 112, in get_response
    response = wrapped_callback(request, *callback_args, **callback_kwargs)
  File "/home/sulakshm/work/django/rest/automon/gps/views.py", line 59, in update
    return render(request, 'gps/update.html', {'form' : form, 'node' : id})
  File "/usr/lib/python2.6/site-packages/django/shortcuts/__init__.py", line 53, in render
    return HttpResponse(loader.render_to_string(*args, **kwargs),
  File "/usr/lib/python2.6/site-packages/django/template/loader.py", line 169, in render_to_string
    return t.render(context_instance)
  File "/usr/lib/python2.6/site-packages/django/template/base.py", line 140, in render
    return self._render(context)
  File "/usr/lib/python2.6/site-packages/django/template/base.py", line 134, in _render
    return self.nodelist.render(context)
  File "/usr/lib/python2.6/site-packages/django/template/base.py", line 840, in render
    bit = self.render_node(node, context)
  File "/usr/lib/python2.6/site-packages/django/template/debug.py", line 78, in render_node
    return node.render(context)
  File "/usr/lib/python2.6/site-packages/django/template/defaulttags.py", line 447, in render
    six.reraise(*exc_info)
  File "/usr/lib/python2.6/site-packages/django/template/defaulttags.py", line 433, in render
    url = reverse(view_name, args=args, kwargs=kwargs, current_app=context.current_app)
  File "/usr/lib/python2.6/site-packages/django/core/urlresolvers.py", line 536, in reverse
    return iri_to_uri(resolver._reverse_with_prefix(view, prefix, *args, **kwargs))
  File "/usr/lib/python2.6/site-packages/django/core/urlresolvers.py", line 456, in _reverse_with_prefix
    (lookup_view_s, args, kwargs, len(patterns), patterns))
NoReverseMatch: Reverse for 'update' with arguments '('',)' and keyword arguments '{}' not found. 1 pattern(s) tried: [u'gps/(?P<id>\\d+)/update$']
(0.001) QUERY = u'SELECT "gps_gpsnode"."id", "gps_gpsnode"."ident", "gps_gpsnode"."user_id", "gps_gpsnode"."last_active" FROM "gps_gpsnode" ORDER BY "gps_gpsnode"."last_active" DESC' - PARAMS = (); args=()
(0.001) QUERY = u'SELECT "gps_gpsnode"."id", "gps_gpsnode"."ident", "gps_gpsnode"."user_id", "gps_gpsnode"."last_active" FROM "gps_gpsnode" WHERE "gps_gpsnode"."id" = %s ' - PARAMS = (1,); args=(1,)
(0.000) QUERY = u'SELECT "gps_gpsnodemetrics"."id", "gps_gpsnodemetrics"."node_id", "gps_gpsnodemetrics"."latitude", "gps_gpsnodemetrics"."longitude", "gps_gpsnodemetrics"."accuracy", "gps_gpsnodemetrics"."speed", "gps_gpsnodemetrics"."altitude", "gps_gpsnodemetrics"."nsecTimestamp", "gps_gpsnodemetrics"."bearing", "gps_gpsnodemetrics"."vin", "gps_gpsnodemetrics"."vinLastCached" FROM "gps_gpsnodemetrics" WHERE "gps_gpsnodemetrics"."node_id" = %s ' - PARAMS = (1,); args=(1,)
Internal Server Error: /gps/1/update
Traceback (most recent call last):
  File "/usr/lib/python2.6/site-packages/django/core/handlers/base.py", line 112, in get_response
    response = wrapped_callback(request, *callback_args, **callback_kwargs)
  File "/home/sulakshm/work/django/rest/automon/gps/views.py", line 59, in update
    return render(request, 'gps/update.html', {'form' : form, 'node' : id})
  File "/usr/lib/python2.6/site-packages/django/shortcuts/__init__.py", line 53, in render
    return HttpResponse(loader.render_to_string(*args, **kwargs),
  File "/usr/lib/python2.6/site-packages/django/template/loader.py", line 169, in render_to_string
    return t.render(context_instance)
  File "/usr/lib/python2.6/site-packages/django/template/base.py", line 140, in render
    return self._render(context)
  File "/usr/lib/python2.6/site-packages/django/template/base.py", line 134, in _render
    return self.nodelist.render(context)
  File "/usr/lib/python2.6/site-packages/django/template/base.py", line 840, in render
    bit = self.render_node(node, context)
  File "/usr/lib/python2.6/site-packages/django/template/debug.py", line 78, in render_node
    return node.render(context)
  File "/usr/lib/python2.6/site-packages/django/template/defaulttags.py", line 447, in render
    six.reraise(*exc_info)
  File "/usr/lib/python2.6/site-packages/django/template/defaulttags.py", line 433, in render
    url = reverse(view_name, args=args, kwargs=kwargs, current_app=context.current_app)
  File "/usr/lib/python2.6/site-packages/django/core/urlresolvers.py", line 536, in reverse
    return iri_to_uri(resolver._reverse_with_prefix(view, prefix, *args, **kwargs))
  File "/usr/lib/python2.6/site-packages/django/core/urlresolvers.py", line 456, in _reverse_with_prefix
    (lookup_view_s, args, kwargs, len(patterns), patterns))
NoReverseMatch: Reverse for 'update' with arguments '('',)' and keyword arguments '{}' not found. 1 pattern(s) tried: [u'gps/(?P<id>\\d+)/update$']
Internal Server Error: /gps/1/update
Traceback (most recent call last):
  File "/usr/lib/python2.6/site-packages/django/core/handlers/base.py", line 112, in get_response
    response = wrapped_callback(request, *callback_args, **callback_kwargs)
  File "/home/sulakshm/work/django/rest/automon/gps/views.py", line 59, in update
    return render(request, 'gps/update.html', {'form' : form, 'node' : id})
  File "/usr/lib/python2.6/site-packages/django/shortcuts/__init__.py", line 53, in render
    return HttpResponse(loader.render_to_string(*args, **kwargs),
  File "/usr/lib/python2.6/site-packages/django/template/loader.py", line 169, in render_to_string
    return t.render(context_instance)
  File "/usr/lib/python2.6/site-packages/django/template/base.py", line 140, in render
    return self._render(context)
  File "/usr/lib/python2.6/site-packages/django/template/base.py", line 134, in _render
    return self.nodelist.render(context)
  File "/usr/lib/python2.6/site-packages/django/template/base.py", line 840, in render
    bit = self.render_node(node, context)
  File "/usr/lib/python2.6/site-packages/django/template/debug.py", line 78, in render_node
    return node.render(context)
  File "/usr/lib/python2.6/site-packages/django/template/defaulttags.py", line 447, in render
    six.reraise(*exc_info)
  File "/usr/lib/python2.6/site-packages/django/template/defaulttags.py", line 433, in render
    url = reverse(view_name, args=args, kwargs=kwargs, current_app=context.current_app)
  File "/usr/lib/python2.6/site-packages/django/core/urlresolvers.py", line 536, in reverse
    return iri_to_uri(resolver._reverse_with_prefix(view, prefix, *args, **kwargs))
  File "/usr/lib/python2.6/site-packages/django/core/urlresolvers.py", line 456, in _reverse_with_prefix
    (lookup_view_s, args, kwargs, len(patterns), patterns))
NoReverseMatch: Reverse for 'update' with arguments '('',)' and keyword arguments '{}' not found. 1 pattern(s) tried: [u'gps/(?P<id>\\d+)/update$']
(0.001) QUERY = u'SELECT "gps_gpsnode"."id", "gps_gpsnode"."ident", "gps_gpsnode"."user_id", "gps_gpsnode"."last_active" FROM "gps_gpsnode" WHERE "gps_gpsnode"."id" = %s ' - PARAMS = (1,); args=(1,)
(0.000) QUERY = u'SELECT "gps_gpsnodemetrics"."id", "gps_gpsnodemetrics"."node_id", "gps_gpsnodemetrics"."latitude", "gps_gpsnodemetrics"."longitude", "gps_gpsnodemetrics"."accuracy", "gps_gpsnodemetrics"."speed", "gps_gpsnodemetrics"."altitude", "gps_gpsnodemetrics"."nsecTimestamp", "gps_gpsnodemetrics"."bearing", "gps_gpsnodemetrics"."vin", "gps_gpsnodemetrics"."vinLastCached" FROM "gps_gpsnodemetrics" WHERE "gps_gpsnodemetrics"."node_id" = %s ' - PARAMS = (1,); args=(1,)
Internal Server Error: /gps/1/update
Traceback (most recent call last):
  File "/usr/lib/python2.6/site-packages/django/core/handlers/base.py", line 112, in get_response
    response = wrapped_callback(request, *callback_args, **callback_kwargs)
  File "/home/sulakshm/work/django/rest/automon/gps/views.py", line 59, in update
    return render(request, 'gps/update.html', {'form' : form, 'node' : id})
  File "/usr/lib/python2.6/site-packages/django/shortcuts/__init__.py", line 53, in render
    return HttpResponse(loader.render_to_string(*args, **kwargs),
  File "/usr/lib/python2.6/site-packages/django/template/loader.py", line 169, in render_to_string
    return t.render(context_instance)
  File "/usr/lib/python2.6/site-packages/django/template/base.py", line 140, in render
    return self._render(context)
  File "/usr/lib/python2.6/site-packages/django/template/base.py", line 134, in _render
    return self.nodelist.render(context)
  File "/usr/lib/python2.6/site-packages/django/template/base.py", line 840, in render
    bit = self.render_node(node, context)
  File "/usr/lib/python2.6/site-packages/django/template/debug.py", line 78, in render_node
    return node.render(context)
  File "/usr/lib/python2.6/site-packages/django/template/defaulttags.py", line 447, in render
    six.reraise(*exc_info)
  File "/usr/lib/python2.6/site-packages/django/template/defaulttags.py", line 433, in render
    url = reverse(view_name, args=args, kwargs=kwargs, current_app=context.current_app)
  File "/usr/lib/python2.6/site-packages/django/core/urlresolvers.py", line 536, in reverse
    return iri_to_uri(resolver._reverse_with_prefix(view, prefix, *args, **kwargs))
  File "/usr/lib/python2.6/site-packages/django/core/urlresolvers.py", line 456, in _reverse_with_prefix
    (lookup_view_s, args, kwargs, len(patterns), patterns))
NoReverseMatch: Reverse for 'update' with arguments '('',)' and keyword arguments '{}' not found. 1 pattern(s) tried: [u'gps/(?P<id>\\d+)/update$']
(0.001) QUERY = u'SELECT "gps_gpsnode"."id", "gps_gpsnode"."ident", "gps_gpsnode"."user_id", "gps_gpsnode"."last_active" FROM "gps_gpsnode" ORDER BY "gps_gpsnode"."last_active" DESC' - PARAMS = (); args=()
(0.001) QUERY = u'SELECT "gps_gpsnode"."id", "gps_gpsnode"."ident", "gps_gpsnode"."user_id", "gps_gpsnode"."last_active" FROM "gps_gpsnode" WHERE "gps_gpsnode"."id" = %s ' - PARAMS = (1,); args=(1,)
(0.000) QUERY = u'SELECT "gps_gpsnodemetrics"."id", "gps_gpsnodemetrics"."node_id", "gps_gpsnodemetrics"."latitude", "gps_gpsnodemetrics"."longitude", "gps_gpsnodemetrics"."accuracy", "gps_gpsnodemetrics"."speed", "gps_gpsnodemetrics"."altitude", "gps_gpsnodemetrics"."nsecTimestamp", "gps_gpsnodemetrics"."bearing", "gps_gpsnodemetrics"."vin", "gps_gpsnodemetrics"."vinLastCached" FROM "gps_gpsnodemetrics" WHERE "gps_gpsnodemetrics"."node_id" = %s ' - PARAMS = (1,); args=(1,)
Internal Server Error: /gps/1/xxx
Traceback (most recent call last):
  File "/usr/lib/python2.6/site-packages/django/core/handlers/base.py", line 112, in get_response
    response = wrapped_callback(request, *callback_args, **callback_kwargs)
  File "/home/sulakshm/work/django/rest/automon/gps/views.py", line 60, in update
    return render(request, 'gps/update.html', {'form' : form, 'node' : id})
  File "/usr/lib/python2.6/site-packages/django/shortcuts/__init__.py", line 53, in render
    return HttpResponse(loader.render_to_string(*args, **kwargs),
  File "/usr/lib/python2.6/site-packages/django/template/loader.py", line 169, in render_to_string
    return t.render(context_instance)
  File "/usr/lib/python2.6/site-packages/django/template/base.py", line 140, in render
    return self._render(context)
  File "/usr/lib/python2.6/site-packages/django/template/base.py", line 134, in _render
    return self.nodelist.render(context)
  File "/usr/lib/python2.6/site-packages/django/template/base.py", line 840, in render
    bit = self.render_node(node, context)
  File "/usr/lib/python2.6/site-packages/django/template/debug.py", line 78, in render_node
    return node.render(context)
  File "/usr/lib/python2.6/site-packages/django/template/defaulttags.py", line 447, in render
    six.reraise(*exc_info)
  File "/usr/lib/python2.6/site-packages/django/template/defaulttags.py", line 433, in render
    url = reverse(view_name, args=args, kwargs=kwargs, current_app=context.current_app)
  File "/usr/lib/python2.6/site-packages/django/core/urlresolvers.py", line 536, in reverse
    return iri_to_uri(resolver._reverse_with_prefix(view, prefix, *args, **kwargs))
  File "/usr/lib/python2.6/site-packages/django/core/urlresolvers.py", line 456, in _reverse_with_prefix
    (lookup_view_s, args, kwargs, len(patterns), patterns))
NoReverseMatch: Reverse for 'update' with arguments '('',)' and keyword arguments '{}' not found. 1 pattern(s) tried: [u'gps/(?P<id>\\d+)/xxx$']
Internal Server Error: /gps/1/xxx
Traceback (most recent call last):
  File "/usr/lib/python2.6/site-packages/django/core/handlers/base.py", line 112, in get_response
    response = wrapped_callback(request, *callback_args, **callback_kwargs)
  File "/home/sulakshm/work/django/rest/automon/gps/views.py", line 60, in update
    return render(request, 'gps/update.html', {'form' : form, 'node' : id})
  File "/usr/lib/python2.6/site-packages/django/shortcuts/__init__.py", line 53, in render
    return HttpResponse(loader.render_to_string(*args, **kwargs),
  File "/usr/lib/python2.6/site-packages/django/template/loader.py", line 169, in render_to_string
    return t.render(context_instance)
  File "/usr/lib/python2.6/site-packages/django/template/base.py", line 140, in render
    return self._render(context)
  File "/usr/lib/python2.6/site-packages/django/template/base.py", line 134, in _render
    return self.nodelist.render(context)
  File "/usr/lib/python2.6/site-packages/django/template/base.py", line 840, in render
    bit = self.render_node(node, context)
  File "/usr/lib/python2.6/site-packages/django/template/debug.py", line 78, in render_node
    return node.render(context)
  File "/usr/lib/python2.6/site-packages/django/template/defaulttags.py", line 447, in render
    six.reraise(*exc_info)
  File "/usr/lib/python2.6/site-packages/django/template/defaulttags.py", line 433, in render
    url = reverse(view_name, args=args, kwargs=kwargs, current_app=context.current_app)
  File "/usr/lib/python2.6/site-packages/django/core/urlresolvers.py", line 536, in reverse
    return iri_to_uri(resolver._reverse_with_prefix(view, prefix, *args, **kwargs))
  File "/usr/lib/python2.6/site-packages/django/core/urlresolvers.py", line 456, in _reverse_with_prefix
    (lookup_view_s, args, kwargs, len(patterns), patterns))
NoReverseMatch: Reverse for 'update' with arguments '('',)' and keyword arguments '{}' not found. 1 pattern(s) tried: [u'gps/(?P<id>\\d+)/xxx$']
Internal Server Error: /gps/1/xxx
Traceback (most recent call last):
  File "/usr/lib/python2.6/site-packages/django/core/handlers/base.py", line 112, in get_response
    response = wrapped_callback(request, *callback_args, **callback_kwargs)
  File "/home/sulakshm/work/django/rest/automon/gps/views.py", line 60, in update
    return render(request, 'gps/update.html', {'form' : form, 'node' : id})
  File "/usr/lib/python2.6/site-packages/django/shortcuts/__init__.py", line 53, in render
    return HttpResponse(loader.render_to_string(*args, **kwargs),
  File "/usr/lib/python2.6/site-packages/django/template/loader.py", line 169, in render_to_string
    return t.render(context_instance)
  File "/usr/lib/python2.6/site-packages/django/template/base.py", line 140, in render
    return self._render(context)
  File "/usr/lib/python2.6/site-packages/django/template/base.py", line 134, in _render
    return self.nodelist.render(context)
  File "/usr/lib/python2.6/site-packages/django/template/base.py", line 840, in render
    bit = self.render_node(node, context)
  File "/usr/lib/python2.6/site-packages/django/template/debug.py", line 78, in render_node
    return node.render(context)
  File "/usr/lib/python2.6/site-packages/django/template/defaulttags.py", line 447, in render
    six.reraise(*exc_info)
  File "/usr/lib/python2.6/site-packages/django/template/defaulttags.py", line 433, in render
    url = reverse(view_name, args=args, kwargs=kwargs, current_app=context.current_app)
  File "/usr/lib/python2.6/site-packages/django/core/urlresolvers.py", line 536, in reverse
    return iri_to_uri(resolver._reverse_with_prefix(view, prefix, *args, **kwargs))
  File "/usr/lib/python2.6/site-packages/django/core/urlresolvers.py", line 456, in _reverse_with_prefix
    (lookup_view_s, args, kwargs, len(patterns), patterns))
NoReverseMatch: Reverse for 'update' with arguments '('',)' and keyword arguments '{}' not found. 1 pattern(s) tried: [u'gps/(?P<id>\\d+)/xxx$']
Internal Server Error: /gps/1/xxx
Traceback (most recent call last):
  File "/usr/lib/python2.6/site-packages/django/core/handlers/base.py", line 112, in get_response
    response = wrapped_callback(request, *callback_args, **callback_kwargs)
  File "/home/sulakshm/work/django/rest/automon/gps/views.py", line 60, in update
    return render(request, 'gps/update.html', {'form' : form, 'node' : id})
  File "/usr/lib/python2.6/site-packages/django/shortcuts/__init__.py", line 53, in render
    return HttpResponse(loader.render_to_string(*args, **kwargs),
  File "/usr/lib/python2.6/site-packages/django/template/loader.py", line 169, in render_to_string
    return t.render(context_instance)
  File "/usr/lib/python2.6/site-packages/django/template/base.py", line 140, in render
    return self._render(context)
  File "/usr/lib/python2.6/site-packages/django/template/base.py", line 134, in _render
    return self.nodelist.render(context)
  File "/usr/lib/python2.6/site-packages/django/template/base.py", line 840, in render
    bit = self.render_node(node, context)
  File "/usr/lib/python2.6/site-packages/django/template/debug.py", line 78, in render_node
    return node.render(context)
  File "/usr/lib/python2.6/site-packages/django/template/defaulttags.py", line 447, in render
    six.reraise(*exc_info)
  File "/usr/lib/python2.6/site-packages/django/template/defaulttags.py", line 433, in render
    url = reverse(view_name, args=args, kwargs=kwargs, current_app=context.current_app)
  File "/usr/lib/python2.6/site-packages/django/core/urlresolvers.py", line 536, in reverse
    return iri_to_uri(resolver._reverse_with_prefix(view, prefix, *args, **kwargs))
  File "/usr/lib/python2.6/site-packages/django/core/urlresolvers.py", line 456, in _reverse_with_prefix
    (lookup_view_s, args, kwargs, len(patterns), patterns))
NoReverseMatch: Reverse for 'showAll' with arguments '('',)' and keyword arguments '{}' not found. 1 pattern(s) tried: [u'gps/(?P<id>\\d+)/$']
Internal Server Error: /gps/1/xxx
Traceback (most recent call last):
  File "/usr/lib/python2.6/site-packages/django/core/handlers/base.py", line 112, in get_response
    response = wrapped_callback(request, *callback_args, **callback_kwargs)
  File "/home/sulakshm/work/django/rest/automon/gps/views.py", line 60, in update
    return render(request, 'gps/update.html', {'form' : form, 'node' : id})
  File "/usr/lib/python2.6/site-packages/django/shortcuts/__init__.py", line 53, in render
    return HttpResponse(loader.render_to_string(*args, **kwargs),
  File "/usr/lib/python2.6/site-packages/django/template/loader.py", line 169, in render_to_string
    return t.render(context_instance)
  File "/usr/lib/python2.6/site-packages/django/template/base.py", line 140, in render
    return self._render(context)
  File "/usr/lib/python2.6/site-packages/django/template/base.py", line 134, in _render
    return self.nodelist.render(context)
  File "/usr/lib/python2.6/site-packages/django/template/base.py", line 840, in render
    bit = self.render_node(node, context)
  File "/usr/lib/python2.6/site-packages/django/template/debug.py", line 78, in render_node
    return node.render(context)
  File "/usr/lib/python2.6/site-packages/django/template/defaulttags.py", line 447, in render
    six.reraise(*exc_info)
  File "/usr/lib/python2.6/site-packages/django/template/defaulttags.py", line 433, in render
    url = reverse(view_name, args=args, kwargs=kwargs, current_app=context.current_app)
  File "/usr/lib/python2.6/site-packages/django/core/urlresolvers.py", line 536, in reverse
    return iri_to_uri(resolver._reverse_with_prefix(view, prefix, *args, **kwargs))
  File "/usr/lib/python2.6/site-packages/django/core/urlresolvers.py", line 456, in _reverse_with_prefix
    (lookup_view_s, args, kwargs, len(patterns), patterns))
NoReverseMatch: Reverse for 'showAll' with arguments '('',)' and keyword arguments '{}' not found. 1 pattern(s) tried: [u'gps/(?P<id>\\d+)/$']
Internal Server Error: /gps/1/xxx
Traceback (most recent call last):
  File "/usr/lib/python2.6/site-packages/django/core/handlers/base.py", line 112, in get_response
    response = wrapped_callback(request, *callback_args, **callback_kwargs)
  File "/home/sulakshm/work/django/rest/automon/gps/views.py", line 60, in update
    return render(request, 'gps/update.html', {'form' : form, 'node' : id})
  File "/usr/lib/python2.6/site-packages/django/shortcuts/__init__.py", line 53, in render
    return HttpResponse(loader.render_to_string(*args, **kwargs),
  File "/usr/lib/python2.6/site-packages/django/template/loader.py", line 169, in render_to_string
    return t.render(context_instance)
  File "/usr/lib/python2.6/site-packages/django/template/base.py", line 140, in render
    return self._render(context)
  File "/usr/lib/python2.6/site-packages/django/template/base.py", line 134, in _render
    return self.nodelist.render(context)
  File "/usr/lib/python2.6/site-packages/django/template/base.py", line 840, in render
    bit = self.render_node(node, context)
  File "/usr/lib/python2.6/site-packages/django/template/debug.py", line 78, in render_node
    return node.render(context)
  File "/usr/lib/python2.6/site-packages/django/template/defaulttags.py", line 447, in render
    six.reraise(*exc_info)
  File "/usr/lib/python2.6/site-packages/django/template/defaulttags.py", line 433, in render
    url = reverse(view_name, args=args, kwargs=kwargs, current_app=context.current_app)
  File "/usr/lib/python2.6/site-packages/django/core/urlresolvers.py", line 536, in reverse
    return iri_to_uri(resolver._reverse_with_prefix(view, prefix, *args, **kwargs))
  File "/usr/lib/python2.6/site-packages/django/core/urlresolvers.py", line 456, in _reverse_with_prefix
    (lookup_view_s, args, kwargs, len(patterns), patterns))
NoReverseMatch: Reverse for 'showAll' with arguments '('',)' and keyword arguments '{}' not found. 1 pattern(s) tried: [u'gps/(?P<id>\\d+)/$']
Internal Server Error: /gps/1/xxx
Traceback (most recent call last):
  File "/usr/lib/python2.6/site-packages/django/core/handlers/base.py", line 112, in get_response
    response = wrapped_callback(request, *callback_args, **callback_kwargs)
  File "/home/sulakshm/work/django/rest/automon/gps/views.py", line 60, in update
    return render(request, 'gps/update.html', {'form' : form, 'node' : id})
  File "/usr/lib/python2.6/site-packages/django/shortcuts/__init__.py", line 53, in render
    return HttpResponse(loader.render_to_string(*args, **kwargs),
  File "/usr/lib/python2.6/site-packages/django/template/loader.py", line 169, in render_to_string
    return t.render(context_instance)
  File "/usr/lib/python2.6/site-packages/django/template/base.py", line 140, in render
    return self._render(context)
  File "/usr/lib/python2.6/site-packages/django/template/base.py", line 134, in _render
    return self.nodelist.render(context)
  File "/usr/lib/python2.6/site-packages/django/template/base.py", line 840, in render
    bit = self.render_node(node, context)
  File "/usr/lib/python2.6/site-packages/django/template/debug.py", line 78, in render_node
    return node.render(context)
  File "/usr/lib/python2.6/site-packages/django/template/defaulttags.py", line 447, in render
    six.reraise(*exc_info)
  File "/usr/lib/python2.6/site-packages/django/template/defaulttags.py", line 433, in render
    url = reverse(view_name, args=args, kwargs=kwargs, current_app=context.current_app)
  File "/usr/lib/python2.6/site-packages/django/core/urlresolvers.py", line 536, in reverse
    return iri_to_uri(resolver._reverse_with_prefix(view, prefix, *args, **kwargs))
  File "/usr/lib/python2.6/site-packages/django/core/urlresolvers.py", line 456, in _reverse_with_prefix
    (lookup_view_s, args, kwargs, len(patterns), patterns))
NoReverseMatch: Reverse for 'showAll' with arguments '('',)' and keyword arguments '{}' not found. 1 pattern(s) tried: [u'gps/(?P<id>\\d+)/$']
Internal Server Error: /gps/1/xxx
Traceback (most recent call last):
  File "/usr/lib/python2.6/site-packages/django/core/handlers/base.py", line 112, in get_response
    response = wrapped_callback(request, *callback_args, **callback_kwargs)
  File "/home/sulakshm/work/django/rest/automon/gps/views.py", line 60, in update
    return render(request, 'gps/update.html', {'form' : form, 'node' : id})
  File "/usr/lib/python2.6/site-packages/django/shortcuts/__init__.py", line 53, in render
    return HttpResponse(loader.render_to_string(*args, **kwargs),
  File "/usr/lib/python2.6/site-packages/django/template/loader.py", line 169, in render_to_string
    return t.render(context_instance)
  File "/usr/lib/python2.6/site-packages/django/template/base.py", line 140, in render
    return self._render(context)
  File "/usr/lib/python2.6/site-packages/django/template/base.py", line 134, in _render
    return self.nodelist.render(context)
  File "/usr/lib/python2.6/site-packages/django/template/base.py", line 840, in render
    bit = self.render_node(node, context)
  File "/usr/lib/python2.6/site-packages/django/template/debug.py", line 78, in render_node
    return node.render(context)
  File "/usr/lib/python2.6/site-packages/django/template/defaulttags.py", line 447, in render
    six.reraise(*exc_info)
  File "/usr/lib/python2.6/site-packages/django/template/defaulttags.py", line 433, in render
    url = reverse(view_name, args=args, kwargs=kwargs, current_app=context.current_app)
  File "/usr/lib/python2.6/site-packages/django/core/urlresolvers.py", line 536, in reverse
    return iri_to_uri(resolver._reverse_with_prefix(view, prefix, *args, **kwargs))
  File "/usr/lib/python2.6/site-packages/django/core/urlresolvers.py", line 456, in _reverse_with_prefix
    (lookup_view_s, args, kwargs, len(patterns), patterns))
NoReverseMatch: Reverse for 'showAll' with arguments '('',)' and keyword arguments '{}' not found. 1 pattern(s) tried: [u'gps/(?P<id>\\d+)/$']
Internal Server Error: /gps/1/xxx
Traceback (most recent call last):
  File "/usr/lib/python2.6/site-packages/django/core/handlers/base.py", line 112, in get_response
    response = wrapped_callback(request, *callback_args, **callback_kwargs)
  File "/home/sulakshm/work/django/rest/automon/gps/views.py", line 60, in update
    return render(request, 'gps/update.html', {'form' : form, 'node' : id})
  File "/usr/lib/python2.6/site-packages/django/shortcuts/__init__.py", line 53, in render
    return HttpResponse(loader.render_to_string(*args, **kwargs),
  File "/usr/lib/python2.6/site-packages/django/template/loader.py", line 169, in render_to_string
    return t.render(context_instance)
  File "/usr/lib/python2.6/site-packages/django/template/base.py", line 140, in render
    return self._render(context)
  File "/usr/lib/python2.6/site-packages/django/template/base.py", line 134, in _render
    return self.nodelist.render(context)
  File "/usr/lib/python2.6/site-packages/django/template/base.py", line 840, in render
    bit = self.render_node(node, context)
  File "/usr/lib/python2.6/site-packages/django/template/debug.py", line 78, in render_node
    return node.render(context)
  File "/usr/lib/python2.6/site-packages/django/template/defaulttags.py", line 447, in render
    six.reraise(*exc_info)
  File "/usr/lib/python2.6/site-packages/django/template/defaulttags.py", line 433, in render
    url = reverse(view_name, args=args, kwargs=kwargs, current_app=context.current_app)
  File "/usr/lib/python2.6/site-packages/django/core/urlresolvers.py", line 536, in reverse
    return iri_to_uri(resolver._reverse_with_prefix(view, prefix, *args, **kwargs))
  File "/usr/lib/python2.6/site-packages/django/core/urlresolvers.py", line 456, in _reverse_with_prefix
    (lookup_view_s, args, kwargs, len(patterns), patterns))
NoReverseMatch: Reverse for 'showAll' with arguments '('',)' and keyword arguments '{}' not found. 1 pattern(s) tried: [u'gps/(?P<id>\\d+)/$']
Internal Server Error: /gps/1/xxx
Traceback (most recent call last):
  File "/usr/lib/python2.6/site-packages/django/core/handlers/base.py", line 112, in get_response
    response = wrapped_callback(request, *callback_args, **callback_kwargs)
  File "/home/sulakshm/work/django/rest/automon/gps/views.py", line 60, in update
    return render(request, 'gps/update.html', {'form' : form, 'node' : id})
  File "/usr/lib/python2.6/site-packages/django/shortcuts/__init__.py", line 53, in render
    return HttpResponse(loader.render_to_string(*args, **kwargs),
  File "/usr/lib/python2.6/site-packages/django/template/loader.py", line 169, in render_to_string
    return t.render(context_instance)
  File "/usr/lib/python2.6/site-packages/django/template/base.py", line 140, in render
    return self._render(context)
  File "/usr/lib/python2.6/site-packages/django/template/base.py", line 134, in _render
    return self.nodelist.render(context)
  File "/usr/lib/python2.6/site-packages/django/template/base.py", line 840, in render
    bit = self.render_node(node, context)
  File "/usr/lib/python2.6/site-packages/django/template/debug.py", line 78, in render_node
    return node.render(context)
  File "/usr/lib/python2.6/site-packages/django/template/defaulttags.py", line 447, in render
    six.reraise(*exc_info)
  File "/usr/lib/python2.6/site-packages/django/template/defaulttags.py", line 433, in render
    url = reverse(view_name, args=args, kwargs=kwargs, current_app=context.current_app)
  File "/usr/lib/python2.6/site-packages/django/core/urlresolvers.py", line 536, in reverse
    return iri_to_uri(resolver._reverse_with_prefix(view, prefix, *args, **kwargs))
  File "/usr/lib/python2.6/site-packages/django/core/urlresolvers.py", line 456, in _reverse_with_prefix
    (lookup_view_s, args, kwargs, len(patterns), patterns))
NoReverseMatch: Reverse for 'update' with arguments '('',)' and keyword arguments '{}' not found. 1 pattern(s) tried: [u'gps/(?P<id>\\d+)/xxx$']
(0.001) QUERY = u'SELECT "gps_gpsnode"."id", "gps_gpsnode"."ident", "gps_gpsnode"."user_id", "gps_gpsnode"."last_active" FROM "gps_gpsnode" ORDER BY "gps_gpsnode"."last_active" DESC' - PARAMS = (); args=()
Internal Server Error: /gps/
Traceback (most recent call last):
  File "/usr/lib/python2.6/site-packages/django/core/handlers/base.py", line 112, in get_response
    response = wrapped_callback(request, *callback_args, **callback_kwargs)
  File "/home/sulakshm/work/django/rest/automon/gps/views.py", line 17, in index
    return render(request, 'gps/index.html', {'nodes' : nodes})
  File "/usr/lib/python2.6/site-packages/django/shortcuts/__init__.py", line 53, in render
    return HttpResponse(loader.render_to_string(*args, **kwargs),
  File "/usr/lib/python2.6/site-packages/django/template/loader.py", line 169, in render_to_string
    return t.render(context_instance)
  File "/usr/lib/python2.6/site-packages/django/template/base.py", line 140, in render
    return self._render(context)
  File "/usr/lib/python2.6/site-packages/django/template/base.py", line 134, in _render
    return self.nodelist.render(context)
  File "/usr/lib/python2.6/site-packages/django/template/base.py", line 840, in render
    bit = self.render_node(node, context)
  File "/usr/lib/python2.6/site-packages/django/template/debug.py", line 78, in render_node
    return node.render(context)
  File "/usr/lib/python2.6/site-packages/django/template/defaulttags.py", line 305, in render
    return nodelist.render(context)
  File "/usr/lib/python2.6/site-packages/django/template/base.py", line 840, in render
    bit = self.render_node(node, context)
  File "/usr/lib/python2.6/site-packages/django/template/debug.py", line 78, in render_node
    return node.render(context)
  File "/usr/lib/python2.6/site-packages/django/template/defaulttags.py", line 196, in render
    nodelist.append(node.render(context))
  File "/usr/lib/python2.6/site-packages/django/template/defaulttags.py", line 433, in render
    url = reverse(view_name, args=args, kwargs=kwargs, current_app=context.current_app)
  File "/usr/lib/python2.6/site-packages/django/core/urlresolvers.py", line 536, in reverse
    return iri_to_uri(resolver._reverse_with_prefix(view, prefix, *args, **kwargs))
  File "/usr/lib/python2.6/site-packages/django/core/urlresolvers.py", line 403, in _reverse_with_prefix
    self._populate()
  File "/usr/lib/python2.6/site-packages/django/core/urlresolvers.py", line 290, in _populate
    for name in pattern.reverse_dict:
  File "/usr/lib/python2.6/site-packages/django/core/urlresolvers.py", line 315, in reverse_dict
    self._populate()
  File "/usr/lib/python2.6/site-packages/django/core/urlresolvers.py", line 280, in _populate
    p_pattern = pattern.regex.pattern
  File "/usr/lib/python2.6/site-packages/django/core/urlresolvers.py", line 178, in regex
    (regex, six.text_type(e)))
ImproperlyConfigured: "^(?P<id>\d+)/update/?*$" is not a valid regular expression: multiple repeat
(0.001) QUERY = u'SELECT "gps_gpsnode"."id", "gps_gpsnode"."ident", "gps_gpsnode"."user_id", "gps_gpsnode"."last_active" FROM "gps_gpsnode" ORDER BY "gps_gpsnode"."last_active" DESC' - PARAMS = (); args=()
Internal Server Error: /gps/1/
Traceback (most recent call last):
  File "/usr/lib/python2.6/site-packages/django/core/handlers/base.py", line 112, in get_response
    response = wrapped_callback(request, *callback_args, **callback_kwargs)
  File "/home/sulakshm/work/django/rest/automon/gps/views.py", line 22, in showAll
    node = get_object_or_404(GpsNode, pk=id)
  File "/usr/lib/python2.6/site-packages/django/shortcuts/__init__.py", line 113, in get_object_or_404
    return queryset.get(*args, **kwargs)
  File "/usr/lib/python2.6/site-packages/django/db/models/query.py", line 301, in get
    clone = self.filter(*args, **kwargs)
  File "/usr/lib/python2.6/site-packages/django/db/models/query.py", line 593, in filter
    return self._filter_or_exclude(False, *args, **kwargs)
  File "/usr/lib/python2.6/site-packages/django/db/models/query.py", line 611, in _filter_or_exclude
    clone.query.add_q(Q(*args, **kwargs))
  File "/usr/lib/python2.6/site-packages/django/db/models/sql/query.py", line 1204, in add_q
    clause = self._add_q(where_part, used_aliases)
  File "/usr/lib/python2.6/site-packages/django/db/models/sql/query.py", line 1240, in _add_q
    current_negated=current_negated)
  File "/usr/lib/python2.6/site-packages/django/db/models/sql/query.py", line 1078, in build_filter
    value = value()
TypeError: id() takes exactly one argument (0 given)
(0.000) QUERY = u'SELECT "gps_gpsnode"."id", "gps_gpsnode"."ident", "gps_gpsnode"."user_id", "gps_gpsnode"."last_active" FROM "gps_gpsnode" LIMIT 21' - PARAMS = (); args=()
(0.000) QUERY = u'SELECT "gps_gpsnode"."id", "gps_gpsnode"."ident", "gps_gpsnode"."user_id", "gps_gpsnode"."last_active" FROM "gps_gpsnode" LIMIT 21' - PARAMS = (); args=()
(0.000) QUERY = u'SELECT "gps_gpsnode"."id", "gps_gpsnode"."ident", "gps_gpsnode"."user_id", "gps_gpsnode"."last_active" FROM "gps_gpsnode" LIMIT 21' - PARAMS = (); args=()
(0.000) QUERY = u'SELECT "gps_gpsnode"."id", "gps_gpsnode"."ident", "gps_gpsnode"."user_id", "gps_gpsnode"."last_active" FROM "gps_gpsnode" LIMIT 21' - PARAMS = (); args=()
(0.000) QUERY = u'SELECT "gps_gpsnode"."id", "gps_gpsnode"."ident", "gps_gpsnode"."user_id", "gps_gpsnode"."last_active" FROM "gps_gpsnode" LIMIT 21' - PARAMS = (); args=()
Not Found: /gps/1/kjhkj
(0.001) QUERY = u'SELECT "gps_gpsnode"."id", "gps_gpsnode"."ident", "gps_gpsnode"."user_id", "gps_gpsnode"."last_active" FROM "gps_gpsnode" ORDER BY "gps_gpsnode"."last_active" DESC' - PARAMS = (); args=()
Internal Server Error: /gps/1/
Traceback (most recent call last):
  File "/usr/lib/python2.6/site-packages/django/core/handlers/base.py", line 112, in get_response
    response = wrapped_callback(request, *callback_args, **callback_kwargs)
  File "/home/sulakshm/work/django/rest/automon/gps/views.py", line 22, in showAll
    node = get_object_or_404(GpsNode, pk=id)
  File "/usr/lib/python2.6/site-packages/django/shortcuts/__init__.py", line 113, in get_object_or_404
    return queryset.get(*args, **kwargs)
  File "/usr/lib/python2.6/site-packages/django/db/models/query.py", line 301, in get
    clone = self.filter(*args, **kwargs)
  File "/usr/lib/python2.6/site-packages/django/db/models/query.py", line 593, in filter
    return self._filter_or_exclude(False, *args, **kwargs)
  File "/usr/lib/python2.6/site-packages/django/db/models/query.py", line 611, in _filter_or_exclude
    clone.query.add_q(Q(*args, **kwargs))
  File "/usr/lib/python2.6/site-packages/django/db/models/sql/query.py", line 1204, in add_q
    clause = self._add_q(where_part, used_aliases)
  File "/usr/lib/python2.6/site-packages/django/db/models/sql/query.py", line 1240, in _add_q
    current_negated=current_negated)
  File "/usr/lib/python2.6/site-packages/django/db/models/sql/query.py", line 1078, in build_filter
    value = value()
TypeError: id() takes exactly one argument (0 given)
(0.000) QUERY = u'SELECT "gps_gpsnode"."id", "gps_gpsnode"."ident", "gps_gpsnode"."user_id", "gps_gpsnode"."last_active" FROM "gps_gpsnode" LIMIT 21' - PARAMS = (); args=()
(0.000) QUERY = u'SELECT "gps_gpsnode"."id", "gps_gpsnode"."ident", "gps_gpsnode"."user_id", "gps_gpsnode"."last_active" FROM "gps_gpsnode" LIMIT 21' - PARAMS = (); args=()
(0.000) QUERY = u'SELECT "gps_gpsnode"."id", "gps_gpsnode"."ident", "gps_gpsnode"."user_id", "gps_gpsnode"."last_active" FROM "gps_gpsnode" LIMIT 21' - PARAMS = (); args=()
(0.000) QUERY = u'SELECT "gps_gpsnode"."id", "gps_gpsnode"."ident", "gps_gpsnode"."user_id", "gps_gpsnode"."last_active" FROM "gps_gpsnode" LIMIT 21' - PARAMS = (); args=()
(0.000) QUERY = u'SELECT "gps_gpsnode"."id", "gps_gpsnode"."ident", "gps_gpsnode"."user_id", "gps_gpsnode"."last_active" FROM "gps_gpsnode" LIMIT 21' - PARAMS = (); args=()
(0.001) QUERY = u'SELECT "gps_gpsnode"."id", "gps_gpsnode"."ident", "gps_gpsnode"."user_id", "gps_gpsnode"."last_active" FROM "gps_gpsnode" WHERE "gps_gpsnode"."id" = %s ' - PARAMS = (1,); args=(1,)
(0.000) QUERY = u'SELECT "gps_gpsnodemetrics"."id", "gps_gpsnodemetrics"."node_id", "gps_gpsnodemetrics"."latitude", "gps_gpsnodemetrics"."longitude", "gps_gpsnodemetrics"."accuracy", "gps_gpsnodemetrics"."speed", "gps_gpsnodemetrics"."altitude", "gps_gpsnodemetrics"."nsecTimestamp", "gps_gpsnodemetrics"."bearing", "gps_gpsnodemetrics"."vin", "gps_gpsnodemetrics"."vinLastCached" FROM "gps_gpsnodemetrics" WHERE "gps_gpsnodemetrics"."node_id" = %s ' - PARAMS = (1,); args=(1,)
Internal Server Error: /gps/1/update
Traceback (most recent call last):
  File "/usr/lib/python2.6/site-packages/django/core/handlers/base.py", line 112, in get_response
    response = wrapped_callback(request, *callback_args, **callback_kwargs)
  File "/home/sulakshm/work/django/rest/automon/gps/views.py", line 60, in update
    return render(request, 'gps/update.html', {'form' : form, 'node' : id})
  File "/usr/lib/python2.6/site-packages/django/shortcuts/__init__.py", line 53, in render
    return HttpResponse(loader.render_to_string(*args, **kwargs),
  File "/usr/lib/python2.6/site-packages/django/template/loader.py", line 169, in render_to_string
    return t.render(context_instance)
  File "/usr/lib/python2.6/site-packages/django/template/base.py", line 140, in render
    return self._render(context)
  File "/usr/lib/python2.6/site-packages/django/template/base.py", line 134, in _render
    return self.nodelist.render(context)
  File "/usr/lib/python2.6/site-packages/django/template/base.py", line 840, in render
    bit = self.render_node(node, context)
  File "/usr/lib/python2.6/site-packages/django/template/debug.py", line 78, in render_node
    return node.render(context)
  File "/usr/lib/python2.6/site-packages/django/template/defaulttags.py", line 447, in render
    six.reraise(*exc_info)
  File "/usr/lib/python2.6/site-packages/django/template/defaulttags.py", line 433, in render
    url = reverse(view_name, args=args, kwargs=kwargs, current_app=context.current_app)
  File "/usr/lib/python2.6/site-packages/django/core/urlresolvers.py", line 536, in reverse
    return iri_to_uri(resolver._reverse_with_prefix(view, prefix, *args, **kwargs))
  File "/usr/lib/python2.6/site-packages/django/core/urlresolvers.py", line 456, in _reverse_with_prefix
    (lookup_view_s, args, kwargs, len(patterns), patterns))
NoReverseMatch: Reverse for 'update' with arguments '('',)' and keyword arguments '{}' not found. 1 pattern(s) tried: [u'gps/(?P<id>\\d+)/update$']
(0.001) QUERY = u'SELECT "gps_gpsnode"."id", "gps_gpsnode"."ident", "gps_gpsnode"."user_id", "gps_gpsnode"."last_active" FROM "gps_gpsnode" ORDER BY "gps_gpsnode"."last_active" DESC' - PARAMS = (); args=()
(0.001) QUERY = u'SELECT "gps_gpsnode"."id", "gps_gpsnode"."ident", "gps_gpsnode"."user_id", "gps_gpsnode"."last_active" FROM "gps_gpsnode" WHERE "gps_gpsnode"."id" = %s ' - PARAMS = (1,); args=(1,)
(0.000) QUERY = u'SELECT "gps_gpsnodemetrics"."id", "gps_gpsnodemetrics"."node_id", "gps_gpsnodemetrics"."latitude", "gps_gpsnodemetrics"."longitude", "gps_gpsnodemetrics"."accuracy", "gps_gpsnodemetrics"."speed", "gps_gpsnodemetrics"."altitude", "gps_gpsnodemetrics"."nsecTimestamp", "gps_gpsnodemetrics"."bearing", "gps_gpsnodemetrics"."vin", "gps_gpsnodemetrics"."vinLastCached" FROM "gps_gpsnodemetrics" WHERE "gps_gpsnodemetrics"."node_id" = %s ' - PARAMS = (1,); args=(1,)
Internal Server Error: /gps/1/update
Traceback (most recent call last):
  File "/usr/lib/python2.6/site-packages/django/core/handlers/base.py", line 112, in get_response
    response = wrapped_callback(request, *callback_args, **callback_kwargs)
  File "/home/sulakshm/work/django/rest/automon/gps/views.py", line 60, in update
    return render(request, 'gps/update.html', {'form' : form, 'node' : id})
  File "/usr/lib/python2.6/site-packages/django/shortcuts/__init__.py", line 53, in render
    return HttpResponse(loader.render_to_string(*args, **kwargs),
  File "/usr/lib/python2.6/site-packages/django/template/loader.py", line 169, in render_to_string
    return t.render(context_instance)
  File "/usr/lib/python2.6/site-packages/django/template/base.py", line 140, in render
    return self._render(context)
  File "/usr/lib/python2.6/site-packages/django/template/base.py", line 134, in _render
    return self.nodelist.render(context)
  File "/usr/lib/python2.6/site-packages/django/template/base.py", line 840, in render
    bit = self.render_node(node, context)
  File "/usr/lib/python2.6/site-packages/django/template/debug.py", line 78, in render_node
    return node.render(context)
  File "/usr/lib/python2.6/site-packages/django/template/defaulttags.py", line 447, in render
    six.reraise(*exc_info)
  File "/usr/lib/python2.6/site-packages/django/template/defaulttags.py", line 433, in render
    url = reverse(view_name, args=args, kwargs=kwargs, current_app=context.current_app)
  File "/usr/lib/python2.6/site-packages/django/core/urlresolvers.py", line 536, in reverse
    return iri_to_uri(resolver._reverse_with_prefix(view, prefix, *args, **kwargs))
  File "/usr/lib/python2.6/site-packages/django/core/urlresolvers.py", line 456, in _reverse_with_prefix
    (lookup_view_s, args, kwargs, len(patterns), patterns))
NoReverseMatch: Reverse for 'test' with arguments '('',)' and keyword arguments '{}' not found. 1 pattern(s) tried: [u'gps/(?P<id>\\d+)/update$']
Internal Server Error: /gps/1/update
Traceback (most recent call last):
  File "/usr/lib/python2.6/site-packages/django/core/handlers/base.py", line 112, in get_response
    response = wrapped_callback(request, *callback_args, **callback_kwargs)
  File "/home/sulakshm/work/django/rest/automon/gps/views.py", line 60, in update
    return render(request, 'gps/update.html', {'form' : form, 'node' : id})
  File "/usr/lib/python2.6/site-packages/django/shortcuts/__init__.py", line 53, in render
    return HttpResponse(loader.render_to_string(*args, **kwargs),
  File "/usr/lib/python2.6/site-packages/django/template/loader.py", line 169, in render_to_string
    return t.render(context_instance)
  File "/usr/lib/python2.6/site-packages/django/template/base.py", line 140, in render
    return self._render(context)
  File "/usr/lib/python2.6/site-packages/django/template/base.py", line 134, in _render
    return self.nodelist.render(context)
  File "/usr/lib/python2.6/site-packages/django/template/base.py", line 840, in render
    bit = self.render_node(node, context)
  File "/usr/lib/python2.6/site-packages/django/template/debug.py", line 78, in render_node
    return node.render(context)
  File "/usr/lib/python2.6/site-packages/django/template/defaulttags.py", line 424, in render
    raise NoReverseMatch("'url' requires a non-empty first argument. "
NoReverseMatch: 'url' requires a non-empty first argument. The syntax changed in Django 1.5, see the docs.
Internal Server Error: /gps/1/update
Traceback (most recent call last):
  File "/usr/lib/python2.6/site-packages/django/core/handlers/base.py", line 112, in get_response
    response = wrapped_callback(request, *callback_args, **callback_kwargs)
  File "/home/sulakshm/work/django/rest/automon/gps/views.py", line 60, in update
    return render(request, 'gps/update.html', {'form' : form, 'node' : id})
  File "/usr/lib/python2.6/site-packages/django/shortcuts/__init__.py", line 53, in render
    return HttpResponse(loader.render_to_string(*args, **kwargs),
  File "/usr/lib/python2.6/site-packages/django/template/loader.py", line 169, in render_to_string
    return t.render(context_instance)
  File "/usr/lib/python2.6/site-packages/django/template/base.py", line 140, in render
    return self._render(context)
  File "/usr/lib/python2.6/site-packages/django/template/base.py", line 134, in _render
    return self.nodelist.render(context)
  File "/usr/lib/python2.6/site-packages/django/template/base.py", line 840, in render
    bit = self.render_node(node, context)
  File "/usr/lib/python2.6/site-packages/django/template/debug.py", line 78, in render_node
    return node.render(context)
  File "/usr/lib/python2.6/site-packages/django/template/defaulttags.py", line 424, in render
    raise NoReverseMatch("'url' requires a non-empty first argument. "
NoReverseMatch: 'url' requires a non-empty first argument. The syntax changed in Django 1.5, see the docs.
Internal Server Error: /gps/1/update
Traceback (most recent call last):
  File "/usr/lib/python2.6/site-packages/django/core/handlers/base.py", line 112, in get_response
    response = wrapped_callback(request, *callback_args, **callback_kwargs)
  File "/home/sulakshm/work/django/rest/automon/gps/views.py", line 60, in update
    return render(request, 'gps/update.html', {'form' : form, 'node' : id})
  File "/usr/lib/python2.6/site-packages/django/shortcuts/__init__.py", line 53, in render
    return HttpResponse(loader.render_to_string(*args, **kwargs),
  File "/usr/lib/python2.6/site-packages/django/template/loader.py", line 169, in render_to_string
    return t.render(context_instance)
  File "/usr/lib/python2.6/site-packages/django/template/base.py", line 140, in render
    return self._render(context)
  File "/usr/lib/python2.6/site-packages/django/template/base.py", line 134, in _render
    return self.nodelist.render(context)
  File "/usr/lib/python2.6/site-packages/django/template/base.py", line 840, in render
    bit = self.render_node(node, context)
  File "/usr/lib/python2.6/site-packages/django/template/debug.py", line 78, in render_node
    return node.render(context)
  File "/usr/lib/python2.6/site-packages/django/template/defaulttags.py", line 424, in render
    raise NoReverseMatch("'url' requires a non-empty first argument. "
NoReverseMatch: 'url' requires a non-empty first argument. The syntax changed in Django 1.5, see the docs.
Internal Server Error: /gps/1/update
Traceback (most recent call last):
  File "/usr/lib/python2.6/site-packages/django/core/handlers/base.py", line 112, in get_response
    response = wrapped_callback(request, *callback_args, **callback_kwargs)
  File "/home/sulakshm/work/django/rest/automon/gps/views.py", line 60, in update
    return render(request, 'gps/update.html', {'form' : form, 'node' : id})
  File "/usr/lib/python2.6/site-packages/django/shortcuts/__init__.py", line 53, in render
    return HttpResponse(loader.render_to_string(*args, **kwargs),
  File "/usr/lib/python2.6/site-packages/django/template/loader.py", line 169, in render_to_string
    return t.render(context_instance)
  File "/usr/lib/python2.6/site-packages/django/template/base.py", line 140, in render
    return self._render(context)
  File "/usr/lib/python2.6/site-packages/django/template/base.py", line 134, in _render
    return self.nodelist.render(context)
  File "/usr/lib/python2.6/site-packages/django/template/base.py", line 840, in render
    bit = self.render_node(node, context)
  File "/usr/lib/python2.6/site-packages/django/template/debug.py", line 78, in render_node
    return node.render(context)
  File "/usr/lib/python2.6/site-packages/django/template/defaulttags.py", line 424, in render
    raise NoReverseMatch("'url' requires a non-empty first argument. "
NoReverseMatch: 'url' requires a non-empty first argument. The syntax changed in Django 1.5, see the docs.
Internal Server Error: /gps/1/update
Traceback (most recent call last):
  File "/usr/lib/python2.6/site-packages/django/core/handlers/base.py", line 112, in get_response
    response = wrapped_callback(request, *callback_args, **callback_kwargs)
  File "/home/sulakshm/work/django/rest/automon/gps/views.py", line 60, in update
    return render(request, 'gps/update.html', {'form' : form, 'node' : id})
  File "/usr/lib/python2.6/site-packages/django/shortcuts/__init__.py", line 53, in render
    return HttpResponse(loader.render_to_string(*args, **kwargs),
  File "/usr/lib/python2.6/site-packages/django/template/loader.py", line 162, in render_to_string
    t = get_template(template_name)
  File "/usr/lib/python2.6/site-packages/django/template/loader.py", line 138, in get_template
    template, origin = find_template(template_name)
  File "/usr/lib/python2.6/site-packages/django/template/loader.py", line 127, in find_template
    source, display_name = loader(name, dirs)
  File "/usr/lib/python2.6/site-packages/django/template/loader.py", line 43, in __call__
    return self.load_template(template_name, template_dirs)
  File "/usr/lib/python2.6/site-packages/django/template/loader.py", line 49, in load_template
    template = get_template_from_string(source, origin, template_name)
  File "/usr/lib/python2.6/site-packages/django/template/loader.py", line 149, in get_template_from_string
    return Template(source, origin, name)
  File "/usr/lib/python2.6/site-packages/django/template/base.py", line 125, in __init__
    self.nodelist = compile_string(template_string, origin)
  File "/usr/lib/python2.6/site-packages/django/template/base.py", line 153, in compile_string
    return parser.parse()
  File "/usr/lib/python2.6/site-packages/django/template/base.py", line 278, in parse
    compiled_result = compile_func(self, token)
  File "/usr/lib/python2.6/site-packages/django/template/defaulttags.py", line 1306, in url
    viewname = parser.compile_filter(bits[1])
  File "/usr/lib/python2.6/site-packages/django/template/base.py", line 360, in compile_filter
    return FilterExpression(token, self)
  File "/usr/lib/python2.6/site-packages/django/template/base.py", line 577, in __init__
    "from '%s'" % (token[upto:], token))
TemplateSyntaxError: Could not parse the remainder: ':update' from 'gps:update'. The syntax of 'url' changed in Django 1.5, see the docs.
Internal Server Error: /gps/1/update
Traceback (most recent call last):
  File "/usr/lib/python2.6/site-packages/django/core/handlers/base.py", line 112, in get_response
    response = wrapped_callback(request, *callback_args, **callback_kwargs)
  File "/home/sulakshm/work/django/rest/automon/gps/views.py", line 60, in update
    return render(request, 'gps/update.html', {'form' : form, 'node' : id})
  File "/usr/lib/python2.6/site-packages/django/shortcuts/__init__.py", line 53, in render
    return HttpResponse(loader.render_to_string(*args, **kwargs),
  File "/usr/lib/python2.6/site-packages/django/template/loader.py", line 169, in render_to_string
    return t.render(context_instance)
  File "/usr/lib/python2.6/site-packages/django/template/base.py", line 140, in render
    return self._render(context)
  File "/usr/lib/python2.6/site-packages/django/template/base.py", line 134, in _render
    return self.nodelist.render(context)
  File "/usr/lib/python2.6/site-packages/django/template/base.py", line 840, in render
    bit = self.render_node(node, context)
  File "/usr/lib/python2.6/site-packages/django/template/debug.py", line 78, in render_node
    return node.render(context)
  File "/usr/lib/python2.6/site-packages/django/template/defaulttags.py", line 447, in render
    six.reraise(*exc_info)
  File "/usr/lib/python2.6/site-packages/django/template/defaulttags.py", line 433, in render
    url = reverse(view_name, args=args, kwargs=kwargs, current_app=context.current_app)
  File "/usr/lib/python2.6/site-packages/django/core/urlresolvers.py", line 536, in reverse
    return iri_to_uri(resolver._reverse_with_prefix(view, prefix, *args, **kwargs))
  File "/usr/lib/python2.6/site-packages/django/core/urlresolvers.py", line 456, in _reverse_with_prefix
    (lookup_view_s, args, kwargs, len(patterns), patterns))
NoReverseMatch: Reverse for 'update' with arguments '('',)' and keyword arguments '{}' not found. 0 pattern(s) tried: []
(0.001) QUERY = u'SELECT "gps_gpsnode"."id", "gps_gpsnode"."ident", "gps_gpsnode"."user_id", "gps_gpsnode"."last_active" FROM "gps_gpsnode" ORDER BY "gps_gpsnode"."last_active" DESC' - PARAMS = (); args=()
(0.001) QUERY = u'SELECT "gps_gpsnode"."id", "gps_gpsnode"."ident", "gps_gpsnode"."user_id", "gps_gpsnode"."last_active" FROM "gps_gpsnode" WHERE "gps_gpsnode"."id" = %s ' - PARAMS = (1,); args=(1,)
Internal Server Error: /gps/1/
Traceback (most recent call last):
  File "/usr/lib/python2.6/site-packages/django/core/handlers/base.py", line 112, in get_response
    response = wrapped_callback(request, *callback_args, **callback_kwargs)
  File "/home/sulakshm/work/django/rest/automon/gps/views.py", line 24, in showAll
    return render(request, 'gps/showAll.html', {'node' : node})
  File "/usr/lib/python2.6/site-packages/django/shortcuts/__init__.py", line 53, in render
    return HttpResponse(loader.render_to_string(*args, **kwargs),
  File "/usr/lib/python2.6/site-packages/django/template/loader.py", line 169, in render_to_string
    return t.render(context_instance)
  File "/usr/lib/python2.6/site-packages/django/template/base.py", line 140, in render
    return self._render(context)
  File "/usr/lib/python2.6/site-packages/django/template/base.py", line 134, in _render
    return self.nodelist.render(context)
  File "/usr/lib/python2.6/site-packages/django/template/base.py", line 840, in render
    bit = self.render_node(node, context)
  File "/usr/lib/python2.6/site-packages/django/template/debug.py", line 78, in render_node
    return node.render(context)
  File "/usr/lib/python2.6/site-packages/django/template/defaulttags.py", line 447, in render
    six.reraise(*exc_info)
  File "/usr/lib/python2.6/site-packages/django/template/defaulttags.py", line 433, in render
    url = reverse(view_name, args=args, kwargs=kwargs, current_app=context.current_app)
  File "/usr/lib/python2.6/site-packages/django/core/urlresolvers.py", line 536, in reverse
    return iri_to_uri(resolver._reverse_with_prefix(view, prefix, *args, **kwargs))
  File "/usr/lib/python2.6/site-packages/django/core/urlresolvers.py", line 456, in _reverse_with_prefix
    (lookup_view_s, args, kwargs, len(patterns), patterns))
NoReverseMatch: Reverse for 'update' with arguments '(1,)' and keyword arguments '{}' not found. 0 pattern(s) tried: []
(0.001) QUERY = u'SELECT "gps_gpsnode"."id", "gps_gpsnode"."ident", "gps_gpsnode"."user_id", "gps_gpsnode"."last_active" FROM "gps_gpsnode" WHERE "gps_gpsnode"."id" = %s ' - PARAMS = (1,); args=(1,)
(0.000) QUERY = u'SELECT "gps_gpsnodemetrics"."id", "gps_gpsnodemetrics"."node_id", "gps_gpsnodemetrics"."latitude", "gps_gpsnodemetrics"."longitude", "gps_gpsnodemetrics"."accuracy", "gps_gpsnodemetrics"."speed", "gps_gpsnodemetrics"."altitude", "gps_gpsnodemetrics"."nsecTimestamp", "gps_gpsnodemetrics"."bearing", "gps_gpsnodemetrics"."vin", "gps_gpsnodemetrics"."vinLastCached" FROM "gps_gpsnodemetrics" WHERE "gps_gpsnodemetrics"."node_id" = %s ' - PARAMS = (1,); args=(1,)
Internal Server Error: /gps/1/update
Traceback (most recent call last):
  File "/usr/lib/python2.6/site-packages/django/core/handlers/base.py", line 112, in get_response
    response = wrapped_callback(request, *callback_args, **callback_kwargs)
  File "/home/sulakshm/work/django/rest/automon/gps/views.py", line 60, in update
    return render(request, 'gps/update.html', {'form' : form, 'node' : id})
  File "/usr/lib/python2.6/site-packages/django/shortcuts/__init__.py", line 53, in render
    return HttpResponse(loader.render_to_string(*args, **kwargs),
  File "/usr/lib/python2.6/site-packages/django/template/loader.py", line 169, in render_to_string
    return t.render(context_instance)
  File "/usr/lib/python2.6/site-packages/django/template/base.py", line 140, in render
    return self._render(context)
  File "/usr/lib/python2.6/site-packages/django/template/base.py", line 134, in _render
    return self.nodelist.render(context)
  File "/usr/lib/python2.6/site-packages/django/template/base.py", line 840, in render
    bit = self.render_node(node, context)
  File "/usr/lib/python2.6/site-packages/django/template/debug.py", line 78, in render_node
    return node.render(context)
  File "/usr/lib/python2.6/site-packages/django/template/defaulttags.py", line 447, in render
    six.reraise(*exc_info)
  File "/usr/lib/python2.6/site-packages/django/template/defaulttags.py", line 433, in render
    url = reverse(view_name, args=args, kwargs=kwargs, current_app=context.current_app)
  File "/usr/lib/python2.6/site-packages/django/core/urlresolvers.py", line 536, in reverse
    return iri_to_uri(resolver._reverse_with_prefix(view, prefix, *args, **kwargs))
  File "/usr/lib/python2.6/site-packages/django/core/urlresolvers.py", line 456, in _reverse_with_prefix
    (lookup_view_s, args, kwargs, len(patterns), patterns))
NoReverseMatch: Reverse for 'update' with arguments '('',)' and keyword arguments '{}' not found. 1 pattern(s) tried: [u'gps/(?P<id>\\d+)/update$']
(0.001) QUERY = u'SELECT "gps_gpsnode"."id", "gps_gpsnode"."ident", "gps_gpsnode"."user_id", "gps_gpsnode"."last_active" FROM "gps_gpsnode" ORDER BY "gps_gpsnode"."last_active" DESC' - PARAMS = (); args=()
(0.001) QUERY = u'SELECT "gps_gpsnode"."id", "gps_gpsnode"."ident", "gps_gpsnode"."user_id", "gps_gpsnode"."last_active" FROM "gps_gpsnode" WHERE "gps_gpsnode"."id" = %s ' - PARAMS = (1,); args=(1,)
(0.000) QUERY = u'SELECT "gps_gpsnodemetrics"."id", "gps_gpsnodemetrics"."node_id", "gps_gpsnodemetrics"."latitude", "gps_gpsnodemetrics"."longitude", "gps_gpsnodemetrics"."accuracy", "gps_gpsnodemetrics"."speed", "gps_gpsnodemetrics"."altitude", "gps_gpsnodemetrics"."nsecTimestamp", "gps_gpsnodemetrics"."bearing", "gps_gpsnodemetrics"."vin", "gps_gpsnodemetrics"."vinLastCached" FROM "gps_gpsnodemetrics" WHERE "gps_gpsnodemetrics"."node_id" = %s ' - PARAMS = (1,); args=(1,)
Internal Server Error: /gps/1/update
Traceback (most recent call last):
  File "/usr/lib/python2.6/site-packages/django/core/handlers/base.py", line 112, in get_response
    response = wrapped_callback(request, *callback_args, **callback_kwargs)
  File "/home/sulakshm/work/django/rest/automon/gps/views.py", line 60, in update
    return render(request, 'gps/update.html', {'form' : form, 'node' : id})
  File "/usr/lib/python2.6/site-packages/django/shortcuts/__init__.py", line 53, in render
    return HttpResponse(loader.render_to_string(*args, **kwargs),
  File "/usr/lib/python2.6/site-packages/django/template/loader.py", line 169, in render_to_string
    return t.render(context_instance)
  File "/usr/lib/python2.6/site-packages/django/template/base.py", line 140, in render
    return self._render(context)
  File "/usr/lib/python2.6/site-packages/django/template/base.py", line 134, in _render
    return self.nodelist.render(context)
  File "/usr/lib/python2.6/site-packages/django/template/base.py", line 840, in render
    bit = self.render_node(node, context)
  File "/usr/lib/python2.6/site-packages/django/template/debug.py", line 78, in render_node
    return node.render(context)
  File "/usr/lib/python2.6/site-packages/django/template/defaulttags.py", line 447, in render
    six.reraise(*exc_info)
  File "/usr/lib/python2.6/site-packages/django/template/defaulttags.py", line 433, in render
    url = reverse(view_name, args=args, kwargs=kwargs, current_app=context.current_app)
  File "/usr/lib/python2.6/site-packages/django/core/urlresolvers.py", line 536, in reverse
    return iri_to_uri(resolver._reverse_with_prefix(view, prefix, *args, **kwargs))
  File "/usr/lib/python2.6/site-packages/django/core/urlresolvers.py", line 456, in _reverse_with_prefix
    (lookup_view_s, args, kwargs, len(patterns), patterns))
NoReverseMatch: Reverse for 'update' with arguments '()' and keyword arguments '{u'id': ''}' not found. 1 pattern(s) tried: [u'gps/(?P<id>\\d+)/update$']
Internal Server Error: /gps/1/update
Traceback (most recent call last):
  File "/usr/lib/python2.6/site-packages/django/core/handlers/base.py", line 112, in get_response
    response = wrapped_callback(request, *callback_args, **callback_kwargs)
  File "/home/sulakshm/work/django/rest/automon/gps/views.py", line 60, in update
    return render(request, 'gps/update.html', {'form' : form, 'node' : id})
  File "/usr/lib/python2.6/site-packages/django/shortcuts/__init__.py", line 53, in render
    return HttpResponse(loader.render_to_string(*args, **kwargs),
  File "/usr/lib/python2.6/site-packages/django/template/loader.py", line 169, in render_to_string
    return t.render(context_instance)
  File "/usr/lib/python2.6/site-packages/django/template/base.py", line 140, in render
    return self._render(context)
  File "/usr/lib/python2.6/site-packages/django/template/base.py", line 134, in _render
    return self.nodelist.render(context)
  File "/usr/lib/python2.6/site-packages/django/template/base.py", line 840, in render
    bit = self.render_node(node, context)
  File "/usr/lib/python2.6/site-packages/django/template/debug.py", line 78, in render_node
    return node.render(context)
  File "/usr/lib/python2.6/site-packages/django/template/defaulttags.py", line 447, in render
    six.reraise(*exc_info)
  File "/usr/lib/python2.6/site-packages/django/template/defaulttags.py", line 433, in render
    url = reverse(view_name, args=args, kwargs=kwargs, current_app=context.current_app)
  File "/usr/lib/python2.6/site-packages/django/core/urlresolvers.py", line 536, in reverse
    return iri_to_uri(resolver._reverse_with_prefix(view, prefix, *args, **kwargs))
  File "/usr/lib/python2.6/site-packages/django/core/urlresolvers.py", line 456, in _reverse_with_prefix
    (lookup_view_s, args, kwargs, len(patterns), patterns))
NoReverseMatch: Reverse for 'update' with arguments '()' and keyword arguments '{}' not found. 1 pattern(s) tried: [u'gps/(?P<id>\\d+)/update$']
Internal Server Error: /gps/1/update
Traceback (most recent call last):
  File "/usr/lib/python2.6/site-packages/django/core/handlers/base.py", line 112, in get_response
    response = wrapped_callback(request, *callback_args, **callback_kwargs)
  File "/home/sulakshm/work/django/rest/automon/gps/views.py", line 60, in update
    return render(request, 'gps/update.html', {'form' : form, 'node' : {'id':id}})
  File "/usr/lib/python2.6/site-packages/django/shortcuts/__init__.py", line 53, in render
    return HttpResponse(loader.render_to_string(*args, **kwargs),
  File "/usr/lib/python2.6/site-packages/django/template/loader.py", line 162, in render_to_string
    t = get_template(template_name)
  File "/usr/lib/python2.6/site-packages/django/template/loader.py", line 138, in get_template
    template, origin = find_template(template_name)
  File "/usr/lib/python2.6/site-packages/django/template/loader.py", line 127, in find_template
    source, display_name = loader(name, dirs)
  File "/usr/lib/python2.6/site-packages/django/template/loader.py", line 43, in __call__
    return self.load_template(template_name, template_dirs)
  File "/usr/lib/python2.6/site-packages/django/template/loader.py", line 49, in load_template
    template = get_template_from_string(source, origin, template_name)
  File "/usr/lib/python2.6/site-packages/django/template/loader.py", line 149, in get_template_from_string
    return Template(source, origin, name)
  File "/usr/lib/python2.6/site-packages/django/template/base.py", line 125, in __init__
    self.nodelist = compile_string(template_string, origin)
  File "/usr/lib/python2.6/site-packages/django/template/base.py", line 153, in compile_string
    return parser.parse()
  File "/usr/lib/python2.6/site-packages/django/template/base.py", line 278, in parse
    compiled_result = compile_func(self, token)
  File "/usr/lib/python2.6/site-packages/django/template/defaulttags.py", line 1326, in url
    kwargs[name] = parser.compile_filter(value)
  File "/usr/lib/python2.6/site-packages/django/template/base.py", line 360, in compile_filter
    return FilterExpression(token, self)
  File "/usr/lib/python2.6/site-packages/django/template/base.py", line 577, in __init__
    "from '%s'" % (token[upto:], token))
TemplateSyntaxError: Could not parse the remainder: '}' from 'node.id}'
